Workbook

Sheet BUY OUT
A1: MXN PER USD | D1: ='Glosario Partidas'!M9 -> 17.5
U3: PROYECCION | V3: PROYECCION | W3: PROYECCION | X3: PROYECCION | Y3: PROYECCION | Z3: PROYECCION | AA3: PROYECCION | AB3: PROYECCION | AC3: PROYECCION | AD3: PROYECCION | AE3: PROYECCION | AF3: PROYECCION | AG3: PROYECCION | AH3: PROYECCION | AI3: PROYECCION | AJ3: PROYECCION | AK3: PROYECCION | AL3: PROYECCION | AM3: PROYECCION | AN3: PROYECCION | AO3: PROYECCION | AP3: PROYECCION | AQ3: PROYECCION | AR3: PROYECCION | AS3: PROYECCION | AT3: PROYECCION | AU3: PROYECCION | AV3: PROYECCION | AW3: PROYECCION | AX3: PROYECCION | AY3: PROYECCION | AZ3: PROYECCION | BA3: PROYECCION | BB3: PROYECCION | BC3: PROYECCION | BD3: PROYECCION | BE3: PROYECCION | BF3: PROYECCION | BG3: PROYECCION | BH3: PROYECCION | BI3: PROYECCION | BJ3: PROYECCION | BK3: PROYECCION | BL3: PROYECCION | BM3: PROYECCION | BN3: PROYECCION | BO3: PROYECCION | BP3: PROYECCION | BQ3: PROYECCION | BR3: PROYECCION | BS3: PROYECCION
B4: CONCEPTO | E4: PRESUPUESTO IZ MXN BASE | F4: PPTO MARZO MXN | G4: PPTO ABRIL MXN | H4: PPTO MAYO MXN | I4: PPTO JUNIO MXN | J4: DIF BASE VS. JUNIO | K4: COSTO M2 INTERIOR JUNIO | L4: PRESUPUESTO IZ USD BASE | M4: PPTO JUNIO USD | O4: PPTO | P4: PARAMETRICO | R4: CONTRATADO | S4: NO CONTRATADO | U4: 45792 | V4: 45807 | W4: 45823 | X4: 45838 | Y4: 45853 | Z4: 45868 | AA4: 45884 | AB4: 45899 | AC4: 45915 | AD4: 45930 | AE4: 45945 | AF4: 45960 | AG4: 45976 | AH4: 45991 | AI4: 46006 | AJ4: 46021 | AK4: 46037 | AL4: 46052 | AM4: 46068 | AN4: 46081 | AO4: 46096 | AP4: 46111 | AQ4: 46127 | AR4: 46142 | AS4: 46157 | AT4: 46172 | AU4: 46188 | AV4: 46203 | AW4: 46218 | AX4: 46233 | AY4: 46249 | AZ4: 46264 | BA4: 46280 | BB4: 46295 | BC4: 46310 | BD4: 46325 | BE4: 46341 | BF4: 46356 | BG4: 46371 | BH4: 46386 | BI4: 46402 | BJ4: 46417 | BK4: 46433 | BL4: 46446 | BM4: 46461 | BN4: 46476 | BO4: 46492 | BP4: 46507 | BQ4: 46522 | BR4: 46537 | BS4: 46553 | BT4: CONSTRUCTION SCHEDULE | BU4: COMMENTS
B6: NAUKA BEACHFRONT - GOLF VILLAS
B8: DISEÑO | E8: =E15+E27 -> 2229156.1 | F8: =F15+F27 -> 2029156.1 | G8: =G15+G27 -> 5004956.1 | H8: =H15+H27 -> 4891556.1 | I8: =I15+I27 -> 5091556.1 | J8: =IFERROR(I8/E8-1,0) -> 1.2840734 | K8: =I8/(UNITARIO!$D$9+UNITARIO!$I$9) -> 1739.157 | L8: =E8/$D$1 -> 127380.35 | M8: =I8/$D$1 -> 290946.06 | O8: =O15+O27 -> 5091556.1 | P8: =P15+P27 -> 0 | R8: =R15+R27 -> 4929156.1 | S8: =S15+S27 -> 162400
B9: ARQUITECTURA
B10: Supervision Diseño Iluminacion | E10: 0 | F10: 0 | G10: 0 | H10: 0 | I10: =SUMIFS(Arquitectura!$T:$T,Arquitectura!$C:$C,$B10) -> 0 | J10: =IFERROR(I10/E10-1,0) -> 0 | K10: =I10/(UNITARIO!$D$9+UNITARIO!$I$9) -> 0 | L10: =E10/$D$1 -> 0 | M10: =I10/$D$1 -> 0 | O10: =SUMIFS(Arquitectura!$T:$T,Arquitectura!$C:$C,$B10,Arquitectura!$V:$V,$O$4) -> 0 | P10: =SUMIFS(Arquitectura!$T:$T,Arquitectura!$C:$C,$B10,Arquitectura!$V:$V,$P$4) -> 0 | R10: =SUMIFS(Arquitectura!$T:$T,Arquitectura!$C:$C,$B10,Arquitectura!$W:$W,$R$4) -> 0 | S10: =SUMIFS(Arquitectura!$T:$T,Arquitectura!$C:$C,$B10,Arquitectura!$W:$W,$S$4) -> 0
B11: Diseño Arquitectonico | E11: 0 | F11: 0 | G11: 2700000 | H11: 2700000 | I11: =SUMIFS(Arquitectura!$T:$T,Arquitectura!$C:$C,$B11) -> 2700000 | J11: =IFERROR(I11/E11-1,0) -> 0 | K11: =I11/(UNITARIO!$D$9+UNITARIO!$I$9) -> 922.25714 | L11: =E11/$D$1 -> 0 | M11: =I11/$D$1 -> 154285.71 | O11: =SUMIFS(Arquitectura!$T:$T,Arquitectura!$C:$C,$B11,Arquitectura!$V:$V,$O$4) -> 2700000 | P11: =SUMIFS(Arquitectura!$T:$T,Arquitectura!$C:$C,$B11,Arquitectura!$V:$V,$P$4) -> 0 | R11: =SUMIFS(Arquitectura!$T:$T,Arquitectura!$C:$C,$B11,Arquitectura!$W:$W,$R$4) -> 2700000 | S11: =SUMIFS(Arquitectura!$T:$T,Arquitectura!$C:$C,$B11,Arquitectura!$W:$W,$S$4) -> 0
B12: Diseño Jardineria | E12: 0 | F12: 0 | G12: 208800 | H12: 162400 | I12: =SUMIFS(Arquitectura!$T:$T,Arquitectura!$C:$C,$B12) -> 162400 | J12: =IFERROR(I12/E12-1,0) -> 0 | K12: =I12/(UNITARIO!$D$9+UNITARIO!$I$9) -> 55.472059 | L12: =E12/$D$1 -> 0 | M12: =I12/$D$1 -> 9280 | O12: =SUMIFS(Arquitectura!$T:$T,Arquitectura!$C:$C,$B12,Arquitectura!$V:$V,$O$4) -> 162400 | P12: =SUMIFS(Arquitectura!$T:$T,Arquitectura!$C:$C,$B12,Arquitectura!$V:$V,$P$4) -> 0 | R12: =SUMIFS(Arquitectura!$T:$T,Arquitectura!$C:$C,$B12,Arquitectura!$W:$W,$R$4) -> 0 | S12: =SUMIFS(Arquitectura!$T:$T,Arquitectura!$C:$C,$B12,Arquitectura!$W:$W,$S$4) -> 162400
B13: Cuantificacion M2 | E13: 0 | F13: 0 | G13: 67000 | H13: 0 | I13: =SUMIFS(Arquitectura!$T:$T,Arquitectura!$C:$C,$B13) -> 0 | J13: =IFERROR(I13/E13-1,0) -> 0 | K13: =I13/(UNITARIO!$D$9+UNITARIO!$I$9) -> 0 | L13: =E13/$D$1 -> 0 | M13: =I13/$D$1 -> 0 | O13: =SUMIFS(Arquitectura!$T:$T,Arquitectura!$C:$C,$B13,Arquitectura!$V:$V,$O$4) -> 0 | P13: =SUMIFS(Arquitectura!$T:$T,Arquitectura!$C:$C,$B13,Arquitectura!$V:$V,$P$4) -> 0 | R13: =SUMIFS(Arquitectura!$T:$T,Arquitectura!$C:$C,$B13,Arquitectura!$W:$W,$R$4) -> 0 | S13: =SUMIFS(Arquitectura!$T:$T,Arquitectura!$C:$C,$B13,Arquitectura!$W:$W,$S$4) -> 0
B14: Supervision Diseño Jardineria | E14: 0 | F14: 0 | G14: 0 | H14: 0 | I14: =SUMIFS(Arquitectura!$T:$T,Arquitectura!$C:$C,$B14) -> 0 | J14: =IFERROR(I14/E14-1,0) -> 0 | K14: =I14/(UNITARIO!$D$9+UNITARIO!$I$9) -> 0 | L14: =E14/$D$1 -> 0 | M14: =I14/$D$1 -> 0 | O14: =SUMIFS(Arquitectura!$T:$T,Arquitectura!$C:$C,$B14,Arquitectura!$V:$V,$O$4) -> 0 | P14: =SUMIFS(Arquitectura!$T:$T,Arquitectura!$C:$C,$B14,Arquitectura!$V:$V,$P$4) -> 0 | R14: =SUMIFS(Arquitectura!$T:$T,Arquitectura!$C:$C,$B14,Arquitectura!$W:$W,$R$4) -> 0 | S14: =SUMIFS(Arquitectura!$T:$T,Arquitectura!$C:$C,$B14,Arquitectura!$W:$W,$S$4) -> 0
B15: SUBTOTAL ARQUITECTURA | E15: =SUM(E10:E14) -> 0 | F15: =SUM(F10:F14) -> 0 | G15: =SUM(G10:G14) -> 2975800 | H15: =SUM(H10:H14) -> 2862400 | I15: =SUM(I10:I14) -> 2862400 | J15: =IFERROR(I15/E15-1,0) -> 0 | K15: =I15/(UNITARIO!$D$9+UNITARIO!$I$9) -> 977.7292 | L15: =SUM(L10:L14) -> 0 | M15: =SUM(M10:M14) -> 163565.71 | O15: =SUM(O10:O14) -> 2862400 | P15: =SUM(P10:P14) -> 0 | R15: =SUM(R10:R14) -> 2700000 | S15: =SUM(S10:S14) -> 162400
B17: INGENIERIAS Y TOPOGRAFIA
B18: Topografia Gestoria | E18: 0 | F18: 0 | G18: 0 | H18: 0 | I18: =SUMIFS(Ingenierias_Y_Topografia!$T:$T,Ingenierias_Y_Topografia!$C:$C,$B18) -> 0 | J18: =IFERROR(I18/E18-1,0) -> 0 | K18: =I18/(UNITARIO!$D$9+UNITARIO!$I$9) -> 0 | L18: =E18/$D$1 -> 0 | M18: =I18/$D$1 -> 0 | O18: =SUMIFS(Ingenierias_Y_Topografia!$T:$T,Ingenierias_Y_Topografia!$C:$C,$B18,Ingenierias_Y_Topografia!$V:$V,$O$4) -> 0 | P18: =SUMIFS(Ingenierias_Y_Topografia!$T:$T,Ingenierias_Y_Topografia!$C:$C,$B18,Ingenierias_Y_Topografia!$V:$V,$P$4) -> 0 | R18: =SUMIFS(Ingenierias_Y_Topografia!$T:$T,Ingenierias_Y_Topografia!$C:$C,$B18,Ingenierias_Y_Topografia!$W:$W,$R$4) -> 0 | S18: =SUMIFS(Ingenierias_Y_Topografia!$T:$T,Ingenierias_Y_Topografia!$C:$C,$B18,Ingenierias_Y_Topografia!$W:$W,$S$4) -> 0
B19: Topografia Obra | E19: 0 | F19: 0 | G19: 0 | H19: 0 | I19: =SUMIFS(Ingenierias_Y_Topografia!$T:$T,Ingenierias_Y_Topografia!$C:$C,$B19) -> 0 | J19: =IFERROR(I19/E19-1,0) -> 0 | K19: =I19/(UNITARIO!$D$9+UNITARIO!$I$9) -> 0 | L19: =E19/$D$1 -> 0 | M19: =I19/$D$1 -> 0 | O19: =SUMIFS(Ingenierias_Y_Topografia!$T:$T,Ingenierias_Y_Topografia!$C:$C,$B19,Ingenierias_Y_Topografia!$V:$V,$O$4) -> 0 | P19: =SUMIFS(Ingenierias_Y_Topografia!$T:$T,Ingenierias_Y_Topografia!$C:$C,$B19,Ingenierias_Y_Topografia!$V:$V,$P$4) -> 0 | R19: =SUMIFS(Ingenierias_Y_Topografia!$T:$T,Ingenierias_Y_Topografia!$C:$C,$B19,Ingenierias_Y_Topografia!$W:$W,$R$4) -> 0 | S19: =SUMIFS(Ingenierias_Y_Topografia!$T:$T,Ingenierias_Y_Topografia!$C:$C,$B19,Ingenierias_Y_Topografia!$W:$W,$S$4) -> 0
B20: Mecanica De Suelos | E20: 195384.6 | F20: 195384.6 | G20: 195384.6 | H20: 195384.6 | I20: =SUMIFS(Ingenierias_Y_Topografia!$T:$T,Ingenierias_Y_Topografia!$C:$C,$B20) -> 195384.6 | J20: =IFERROR(I20/E20-1,0) -> 0 | K20: =I20/(UNITARIO!$D$9+UNITARIO!$I$9) -> 66.73883 | L20: =E20/$D$1 -> 11164.834 | M20: =I20/$D$1 -> 11164.834 | O20: =SUMIFS(Ingenierias_Y_Topografia!$T:$T,Ingenierias_Y_Topografia!$C:$C,$B20,Ingenierias_Y_Topografia!$V:$V,$O$4) -> 195384.6 | P20: =SUMIFS(Ingenierias_Y_Topografia!$T:$T,Ingenierias_Y_Topografia!$C:$C,$B20,Ingenierias_Y_Topografia!$V:$V,$P$4) -> 0 | R20: =SUMIFS(Ingenierias_Y_Topografia!$T:$T,Ingenierias_Y_Topografia!$C:$C,$B20,Ingenierias_Y_Topografia!$W:$W,$R$4) -> 195384.6 | S20: =SUMIFS(Ingenierias_Y_Topografia!$T:$T,Ingenierias_Y_Topografia!$C:$C,$B20,Ingenierias_Y_Topografia!$W:$W,$S$4) -> 0
B21: Calculo Estructural | E21: 429200 | F21: 429200 | G21: 429200 | H21: 429200 | I21: =SUMIFS(Ingenierias_Y_Topografia!$T:$T,Ingenierias_Y_Topografia!$C:$C,$B21) -> 429200 | J21: =IFERROR(I21/E21-1,0) -> 0 | K21: =I21/(UNITARIO!$D$9+UNITARIO!$I$9) -> 146.60473 | L21: =E21/$D$1 -> 24525.714 | M21: =I21/$D$1 -> 24525.714 | O21: =SUMIFS(Ingenierias_Y_Topografia!$T:$T,Ingenierias_Y_Topografia!$C:$C,$B21,Ingenierias_Y_Topografia!$V:$V,$O$4) -> 429200 | P21: =SUMIFS(Ingenierias_Y_Topografia!$T:$T,Ingenierias_Y_Topografia!$C:$C,$B21,Ingenierias_Y_Topografia!$V:$V,$P$4) -> 0 | R21: =SUMIFS(Ingenierias_Y_Topografia!$T:$T,Ingenierias_Y_Topografia!$C:$C,$B21,Ingenierias_Y_Topografia!$W:$W,$R$4) -> 429200 | S21: =SUMIFS(Ingenierias_Y_Topografia!$T:$T,Ingenierias_Y_Topografia!$C:$C,$B21,Ingenierias_Y_Topografia!$W:$W,$S$4) -> 0
B22: Diseño HVAC | E22: 150800 | F22: 150800 | G22: 150800 | H22: 150800 | I22: =SUMIFS(Ingenierias_Y_Topografia!$T:$T,Ingenierias_Y_Topografia!$C:$C,$B22) -> 150800 | J22: =IFERROR(I22/E22-1,0) -> 0 | K22: =I22/(UNITARIO!$D$9+UNITARIO!$I$9) -> 51.509769 | L22: =E22/$D$1 -> 8617.1429 | M22: =I22/$D$1 -> 8617.1429 | O22: =SUMIFS(Ingenierias_Y_Topografia!$T:$T,Ingenierias_Y_Topografia!$C:$C,$B22,Ingenierias_Y_Topografia!$V:$V,$O$4) -> 150800 | P22: =SUMIFS(Ingenierias_Y_Topografia!$T:$T,Ingenierias_Y_Topografia!$C:$C,$B22,Ingenierias_Y_Topografia!$V:$V,$P$4) -> 0 | R22: =SUMIFS(Ingenierias_Y_Topografia!$T:$T,Ingenierias_Y_Topografia!$C:$C,$B22,Ingenierias_Y_Topografia!$W:$W,$R$4) -> 150800 | S22: =SUMIFS(Ingenierias_Y_Topografia!$T:$T,Ingenierias_Y_Topografia!$C:$C,$B22,Ingenierias_Y_Topografia!$W:$W,$S$4) -> 0
B23: Diseño Alberca | E23: 139200 | F23: 139200 | G23: 139200 | H23: 139200 | I23: =SUMIFS(Ingenierias_Y_Topografia!$T:$T,Ingenierias_Y_Topografia!$C:$C,$B23) -> 139200 | J23: =IFERROR(I23/E23-1,0) -> 0 | K23: =I23/(UNITARIO!$D$9+UNITARIO!$I$9) -> 47.547479 | L23: =E23/$D$1 -> 7954.2857 | M23: =I23/$D$1 -> 7954.2857 | O23: =SUMIFS(Ingenierias_Y_Topografia!$T:$T,Ingenierias_Y_Topografia!$C:$C,$B23,Ingenierias_Y_Topografia!$V:$V,$O$4) -> 139200 | P23: =SUMIFS(Ingenierias_Y_Topografia!$T:$T,Ingenierias_Y_Topografia!$C:$C,$B23,Ingenierias_Y_Topografia!$V:$V,$P$4) -> 0 | R23: =SUMIFS(Ingenierias_Y_Topografia!$T:$T,Ingenierias_Y_Topografia!$C:$C,$B23,Ingenierias_Y_Topografia!$W:$W,$R$4) -> 139200 | S23: =SUMIFS(Ingenierias_Y_Topografia!$T:$T,Ingenierias_Y_Topografia!$C:$C,$B23,Ingenierias_Y_Topografia!$W:$W,$S$4) -> 0
B24: Diseño Instalaciones HS-E-G | E24: 441728 | F24: 441728 | G24: 441728 | H24: 441728 | I24: =SUMIFS(Ingenierias_Y_Topografia!$T:$T,Ingenierias_Y_Topografia!$C:$C,$B24) -> 441728 | J24: =IFERROR(I24/E24-1,0) -> 0 | K24: =I24/(UNITARIO!$D$9+UNITARIO!$I$9) -> 150.884 | L24: =E24/$D$1 -> 25241.6 | M24: =I24/$D$1 -> 25241.6 | O24: =SUMIFS(Ingenierias_Y_Topografia!$T:$T,Ingenierias_Y_Topografia!$C:$C,$B24,Ingenierias_Y_Topografia!$V:$V,$O$4) -> 441728 | P24: =SUMIFS(Ingenierias_Y_Topografia!$T:$T,Ingenierias_Y_Topografia!$C:$C,$B24,Ingenierias_Y_Topografia!$V:$V,$P$4) -> 0 | R24: =SUMIFS(Ingenierias_Y_Topografia!$T:$T,Ingenierias_Y_Topografia!$C:$C,$B24,Ingenierias_Y_Topografia!$W:$W,$R$4) -> 441728 | S24: =SUMIFS(Ingenierias_Y_Topografia!$T:$T,Ingenierias_Y_Topografia!$C:$C,$B24,Ingenierias_Y_Topografia!$W:$W,$S$4) -> 0
B25: Diseño Iluminacion | D25: Habra extraordinarios | E25: 672843.5 | F25: 672843.5 | G25: 672843.5 | H25: 672843.5 | I25: =SUMIFS(Ingenierias_Y_Topografia!$T:$T,Ingenierias_Y_Topografia!$C:$C,$B25) -> 672843.5 | J25: =IFERROR(I25/E25-1,0) -> 0 | K25: =I25/(UNITARIO!$D$9+UNITARIO!$I$9) -> 229.82767 | L25: =E25/$D$1 -> 38448.2 | M25: =I25/$D$1 -> 38448.2 | O25: =SUMIFS(Ingenierias_Y_Topografia!$T:$T,Ingenierias_Y_Topografia!$C:$C,$B25,Ingenierias_Y_Topografia!$V:$V,$O$4) -> 672843.5 | P25: =SUMIFS(Ingenierias_Y_Topografia!$T:$T,Ingenierias_Y_Topografia!$C:$C,$B25,Ingenierias_Y_Topografia!$V:$V,$P$4) -> 0 | R25: =SUMIFS(Ingenierias_Y_Topografia!$T:$T,Ingenierias_Y_Topografia!$C:$C,$B25,Ingenierias_Y_Topografia!$W:$W,$R$4) -> 672843.5 | S25: =SUMIFS(Ingenierias_Y_Topografia!$T:$T,Ingenierias_Y_Topografia!$C:$C,$B25,Ingenierias_Y_Topografia!$W:$W,$S$4) -> 0
B26: Diseño Acustica | E26: 200000 | F26: 0 | G26: 0 | H26: 0 | I26: =SUMIFS(Ingenierias_Y_Topografia!$T:$T,Ingenierias_Y_Topografia!$C:$C,$B26) -> 200000 | J26: =IFERROR(I26/E26-1,0) -> -1.5543122e-15 | K26: =I26/(UNITARIO!$D$9+UNITARIO!$I$9) -> 68.315344 | L26: =E26/$D$1 -> 11428.571 | M26: =I26/$D$1 -> 11428.571 | O26: =SUMIFS(Ingenierias_Y_Topografia!$T:$T,Ingenierias_Y_Topografia!$C:$C,$B26,Ingenierias_Y_Topografia!$V:$V,$O$4) -> 200000 | P26: =SUMIFS(Ingenierias_Y_Topografia!$T:$T,Ingenierias_Y_Topografia!$C:$C,$B26,Ingenierias_Y_Topografia!$V:$V,$P$4) -> 0 | R26: =SUMIFS(Ingenierias_Y_Topografia!$T:$T,Ingenierias_Y_Topografia!$C:$C,$B26,Ingenierias_Y_Topografia!$W:$W,$R$4) -> 200000 | S26: =SUMIFS(Ingenierias_Y_Topografia!$T:$T,Ingenierias_Y_Topografia!$C:$C,$B26,Ingenierias_Y_Topografia!$W:$W,$S$4) -> 0
B27: SUBTOTAL INGENIERIAS Y TOPOGRAFIA | E27: =SUM(E18:E26) -> 2229156.1 | F27: =SUM(F18:F26) -> 2029156.1 | G27: =SUM(G18:G26) -> 2029156.1 | H27: =SUM(H18:H26) -> 2029156.1 | I27: =SUM(I18:I26) -> 2229156.1 | J27: =IFERROR(I27/E27-1,0) -> -2.220446e-16 | K27: =I27/(UNITARIO!$D$9+UNITARIO!$I$9) -> 761.42782 | L27: =SUM(L18:L25) -> 115951.78 | M27: =SUM(M18:M25) -> 115951.78 | O27: =SUM(O18:O26) -> 2229156.1 | P27: =SUM(P18:P26) -> 0 | R27: =SUM(R18:R26) -> 2229156.1 | S27: =SUM(S18:S26) -> 0
B29: PILAS | E29: =E32 -> 8935744 | F29: =F32 -> 8935744 | G29: =G32 -> 8935744 | H29: =H32 -> 8365678.7 | I29: =I32 -> 8365678.7 | J29: =IFERROR(I29/E29-1,0) -> -0.063796071 | K29: =I29/(UNITARIO!$D$9+UNITARIO!$I$9) -> 2857.5211 | L29: =E29/$D$1 -> 510613.94 | M29: =I29/$D$1 -> 478038.78 | O29: =O32 -> 8365678.7 | P29: =P32 -> 0 | R29: =R32 -> 4182839.3 | S29: =S32 -> 4182839.3
B30: PILAS
B31: Pilas | E31: =4467872.0135*2 -> 8935744 | F31: =4467872.0135*2 -> 8935744 | G31: 8935744 | H31: 8365678.7 | I31: =SUMIFS(Pilas!$T:$T,Pilas!$C:$C,$B31) -> 8365678.7 | J31: =IFERROR(I31/E31-1,0) -> -0.063796071 | K31: =I31/(UNITARIO!$D$9+UNITARIO!$I$9) -> 2857.5211 | L31: =E31/$D$1 -> 510613.94 | M31: =I31/$D$1 -> 478038.78 | O31: =SUMIFS(Pilas!$T:$T,Pilas!$C:$C,$B31,Pilas!$V:$V,$O$4) -> 8365678.7 | P31: =SUMIFS(Pilas!$T:$T,Pilas!$C:$C,$B31,Pilas!$V:$V,$P$4) -> 0 | R31: =SUMIFS(Pilas!$T:$T,Pilas!$C:$C,$B31,Pilas!$W:$W,$R$4) -> 4182839.3 | S31: =SUMIFS(Pilas!$T:$T,Pilas!$C:$C,$B31,Pilas!$W:$W,$S$4) -> 4182839.3
B32: SUBTOTAL PILAS | E32: =SUM(E31) -> 8935744 | F32: =SUM(F31) -> 8935744 | G32: =SUM(G31) -> 8935744 | H32: =SUM(H31) -> 8365678.7 | I32: =SUM(I31) -> 8365678.7 | J32: =IFERROR(I32/E32-1,0) -> -0.063796071 | K32: =I32/(UNITARIO!$D$9+UNITARIO!$I$9) -> 2857.5211 | L32: =SUM(L31) -> 510613.94 | M32: =SUM(M31) -> 478038.78 | O32: =SUM(O31) -> 8365678.7 | P32: =SUM(P31) -> 0 | R32: =SUM(R31) -> 4182839.3 | S32: =SUM(S31) -> 4182839.3
B34: OBRA CIVIL | E34: =E37+E42+E46+E50+E54+E58 -> 84601548 | F34: =F37+F42+F46+F50+F54+F58 -> 82520725 | G34: =G37+G42+G46+G50+G54+G58 -> 82887572 | H34: =H37+H42+H46+H50+H54+H58 -> 95572427 | I34: =I37+I42+I46+I50+I54+I58 -> 95572427 | J34: =IFERROR(I34/E34-1,0) -> 0.12967705 | K34: =I34/(UNITARIO!$D$9+UNITARIO!$I$9) -> 32645.316 | L34: =E34/$D$1 -> 4834374.2 | M34: =I34/$D$1 -> 5461281.5 | O34: =O37+O42+O46+O50+O54+O58 -> 42960535 | P34: =P37+P42+P46+P50+P54+P58 -> 52611892 | R34: =R37+R42+R46+R50+R54+R58 -> 40448326 | S34: =S37+S42+S46+S50+S54+S58 -> 55124101
B35: CONDICIONES GENERALES
B36: Condiciones Generales | E36: =5858713.6783768*2 -> 11717427 | F36: =6751913.6783768*2 -> 13503827 | G36: 14617427 | H36: 18600593 | I36: =SUMIFS('Condiciones Generales'!$T:$T,'Condiciones Generales'!$B:$B,$B36) -> 18600593 | J36: =IFERROR(I36/E36-1,0) -> 0.5874298 | K36: =I36/(UNITARIO!$D$9+UNITARIO!$I$9) -> 6353.5296 | L36: =E36/$D$1 -> 669567.28 | M36: =I36/$D$1 -> 1062891 | O36: =SUMIFS('Condiciones Generales'!$T:$T,'Condiciones Generales'!$B:$B,$B36,'Condiciones Generales'!$V:$V,$O$4) -> 5024417.4 | P36: =SUMIFS('Condiciones Generales'!$T:$T,'Condiciones Generales'!$B:$B,$B36,'Condiciones Generales'!$V:$V,$P$4) -> 13576176 | R36: =SUMIFS('Condiciones Generales'!$T:$T,'Condiciones Generales'!$B:$B,$B36,'Condiciones Generales'!$W:$W,$R$4) -> 2512208.7 | S36: =SUMIFS('Condiciones Generales'!$T:$T,'Condiciones Generales'!$B:$B,$B36,'Condiciones Generales'!$W:$W,$S$4) -> 16088385
B37: SUBTOTAL INDIRECTOS DE OBRA | E37: =SUM(E36) -> 11717427 | F37: =SUM(F36) -> 13503827 | G37: =SUM(G36) -> 14617427 | H37: =SUM(H36) -> 18600593 | I37: =SUM(I36) -> 18600593 | J37: =IFERROR(I37/E37-1,0) -> 0.5874298 | K37: =I37/(UNITARIO!$D$9+UNITARIO!$I$9) -> 6353.5296 | L37: =E37/$D$1 -> 669567.28 | M37: =I37/$D$1 -> 1062891 | O37: =SUM(O36) -> 5024417.4 | P37: =SUM(P36) -> 13576176 | R37: =SUM(R36) -> 2512208.7 | S37: =SUM(S36) -> 16088385
B39: PRELIMINARES
B40: Trabajos Preliminares | E40: =307645.398*2 -> 615290.8 | F40: =244253.718*2 -> 488507.44 | G40: 488507.44 | H40: 488507.44 | I40: =SUMIFS(Preliminares!$T:$T,Preliminares!$C:$C,$B40) -> 488507.44 | J40: =IFERROR(I40/E40-1,0) -> -0.20605437 | K40: =I40/(UNITARIO!$D$9+UNITARIO!$I$9) -> 166.86277 | L40: =E40/$D$1 -> 35159.474 | M40: =I40/$D$1 -> 27914.711 | O40: =SUMIFS(Preliminares!$T:$T,Preliminares!$C:$C,$B40,Preliminares!$V:$V,$O$4) -> 488507.44 | P40: =SUMIFS(Preliminares!$T:$T,Preliminares!$C:$C,$B40,Preliminares!$V:$V,$P$4) -> 0 | R40: =SUMIFS(Preliminares!$T:$T,Preliminares!$C:$C,$B40,Preliminares!$W:$W,$R$4) -> 488507.44 | S40: =SUMIFS(Preliminares!$T:$T,Preliminares!$C:$C,$B40,Preliminares!$W:$W,$S$4) -> 0
B41: Plataformas | E41: =1274117.4592*2 -> 2548234.9 | F41: =1274117.4592*2 -> 2548234.9 | G41: 2548234.9 | H41: 1200109 | I41: =SUMIFS(Preliminares!$T:$T,Preliminares!$C:$C,$B41) -> 1200109 | J41: =IFERROR(I41/E41-1,0) -> -0.52904303 | K41: =I41/(UNITARIO!$D$9+UNITARIO!$I$9) -> 409.92929 | L41: =E41/$D$1 -> 145613.42 | M41: =I41/$D$1 -> 68577.657 | O41: =SUMIFS(Preliminares!$T:$T,Preliminares!$C:$C,$B41,Preliminares!$V:$V,$O$4) -> 1200109 | P41: =SUMIFS(Preliminares!$T:$T,Preliminares!$C:$C,$B41,Preliminares!$V:$V,$P$4) -> 0 | R41: =SUMIFS(Preliminares!$T:$T,Preliminares!$C:$C,$B41,Preliminares!$W:$W,$R$4) -> 1200109 | S41: =SUMIFS(Preliminares!$T:$T,Preliminares!$C:$C,$B41,Preliminares!$W:$W,$S$4) -> 0
B42: SUBTOTAL PRELIMINARES | E42: =SUM(E40:E41) -> 3163525.7 | F42: =SUM(F40:F41) -> 3036742.4 | G42: =SUM(G40:G41) -> 3036742.4 | H42: =SUM(H40:H41) -> 1688616.4 | I42: =SUM(I40:I41) -> 1688616.4 | J42: =IFERROR(I42/E42-1,0) -> -0.46622326 | K42: =I42/(UNITARIO!$D$9+UNITARIO!$I$9) -> 576.79206 | L42: =SUM(L40:L41) -> 180772.9 | M42: =SUM(M40:M41) -> 96492.368 | O42: =SUM(O40:O41) -> 1688616.4 | P42: =SUM(P40:P41) -> 0 | R42: =SUM(R40:R41) -> 1688616.4 | S42: =SUM(S40:S41) -> 0
B44: EXCAVACION - INCLUIDA EN OBRA CIVIL
B45: Excavacion | E45: 0 | F45: 0 | G45: 0 | H45: 0 | I45: =SUMIFS(Excavacion!$T:$T,Excavacion!$C:$C,$B45) -> 0 | J45: =IFERROR(I45/E45-1,0) -> 0 | K45: =I45/(UNITARIO!$D$9+UNITARIO!$I$9) -> 0 | L45: =E45/$D$1 -> 0 | M45: =I45/$D$1 -> 0 | O45: =SUMIFS(Excavacion!$T:$T,Excavacion!$C:$C,$B45,Excavacion!$V:$V,$O$4) -> 0 | P45: =SUMIFS(Excavacion!$T:$T,Excavacion!$C:$C,$B45,Excavacion!$V:$V,$P$4) -> 0 | R45: =SUMIFS(Excavacion!$T:$T,Excavacion!$C:$C,$B45,Excavacion!$W:$W,$R$4) -> 0 | S45: =SUMIFS(Excavacion!$T:$T,Excavacion!$C:$C,$B45,Excavacion!$W:$W,$S$4) -> 0
B46: SUBTOTAL EXCAVACION | E46: =SUM(E45) -> 0 | F46: =SUM(F45) -> 0 | G46: =SUM(G45) -> 0 | H46: =SUM(H45) -> 0 | I46: =SUM(I45) -> 0 | J46: =IFERROR(I46/E46-1,0) -> 0 | K46: =I46/(UNITARIO!$D$9+UNITARIO!$I$9) -> 0 | L46: =SUM(L45) -> 0 | M46: =SUM(M45) -> 0 | O46: =SUM(O45) -> 0 | P46: =SUM(P45) -> 0 | R46: =SUM(R45) -> 0 | S46: =SUM(S45) -> 0
B48: OBRA CIVIL
B49: Obra_Civil | E49: =33935932.845*2 -> 67871866 | F49: =32065713.315*2 -> 64131427 | G49: 63384673 | H49: 72495002 | I49: =SUMIFS(Obra_Civil!$T:$T,Obra_Civil!$B:$B,$B49) -> 66000000 | J49: =IFERROR(I49/E49-1,0) -> -0.027579407 | K49: =I49/(UNITARIO!$D$9+UNITARIO!$I$9) -> 22544.063 | L49: =E49/$D$1 -> 3878392.3 | M49: =I49/$D$1 -> 3771428.6 | O49: =SUMIFS(Obra_Civil!$T:$T,Obra_Civil!$B:$B,$B49,Obra_Civil!$V:$V,$O$4) -> 33000000 | P49: =SUMIFS(Obra_Civil!$T:$T,Obra_Civil!$B:$B,$B49,Obra_Civil!$V:$V,$P$4) -> 33000000 | R49: =SUMIFS(Obra_Civil!$T:$T,Obra_Civil!$B:$B,$B49,Obra_Civil!$W:$W,$R$4) -> 33000000 | S49: =SUMIFS(Obra_Civil!$T:$T,Obra_Civil!$B:$B,$B49,Obra_Civil!$W:$W,$S$4) -> 33000000
...

Sheet UNITARIO
C2: MXN PER USD | D2: ='Glosario Partidas'!M9 -> 17.5
C4: DEPTO | D4: Area Int. Acon. | E4: Area Ext. Techada | F4: Total AIA + AET | H4: DEPTO | I4: Area Int. Acon. | J4: Area Ext. Techada | K4: Total AIA + AET
C5: PB 1 | D5: 322.72 | E5: 106.72 | F5: =D5+E5 -> 429.44 | H5: PB 1 | I5: 322.72 | J5: 106.72 | K5: =I5+J5 -> 429.44
C6: PB 2 | D6: 322.72 | E6: 106.72 | F6: =D6+E6 -> 429.44 | H6: PB 2 | I6: 322.72 | J6: 106.72 | K6: =I6+J6 -> 429.44
C7: N1 + Roof 1 | D7: 409.18 | E7: 153.91 | F7: =D7+E7 -> 563.09 | H7: N1 + Roof 1 | I7: 409.18 | J7: 153.91 | K7: =I7+J7 -> 563.09
C8: N1 + Roof 2 | D8: 409.18 | E8: 153.91 | F8: =D8+E8 -> 563.09 | H8: N1 + Roof 2 | I8: 409.18 | J8: 153.91 | K8: =I8+J8 -> 563.09
C9: Total Torre 1 | D9: =SUM(D5:D8) -> 1463.8 | E9: 521.26 | F9: =D9+E9 -> 1985.06 | H9: Total Torre 1 | I9: =SUM(I5:I8) -> 1463.8 | J9: 521.26 | K9: =I9+J9 -> 1985.06
C11: Area Int. Acon. | H11: Area Int. Acon.
C13: Torre 1 | D13: Base | E13: Mrazo | F13: Abril | H13: Torre 2 | I13: Base | J13: Mrazo | K13: Abril
C14: MXN/M2 | D14: =('BUY OUT'!E172/2)/$D$9 -> 145908.3 | E14: =('BUY OUT'!F172/2)/$D$9 -> 136216.37 | F14: =('BUY OUT'!G172/2)/$D$9 -> 141488.7 | H14: MXN/M2 | I14: =('BUY OUT'!E172/2)/$D$9 -> 145908.3 | J14: =('BUY OUT'!F172/2)/$D$9 -> 136216.37 | K14: =('BUY OUT'!G172/2)/$D$9 -> 141488.7
C16: PB 1 | D16: =$D$14*D5 -> 47087526 | E16: =$E$14*D5 -> 43959747 | F16: =$F$14*D5 -> 45661235 | H16: PB 1 | I16: =$I$14*I5 -> 47087526 | J16: =$J$14*I5 -> 43959747 | K16: =$K$14*I5 -> 45661235
C17: PB 2 | D17: =$D$14*D6 -> 47087526 | E17: =$E$14*D6 -> 43959747 | F17: =$F$14*D6 -> 45661235 | H17: PB 2 | I17: =$I$14*I6 -> 47087526 | J17: =$J$14*I6 -> 43959747 | K17: =$K$14*I6 -> 45661235
C18: N1 + Roof 1 | D18: =$D$14*D7 -> 59702757 | E18: =$E$14*D7 -> 55737014 | F18: =$F$14*D7 -> 57894348 | H18: N1 + Roof 1 | I18: =$I$14*I7 -> 59702757 | J18: =$J$14*I7 -> 55737014 | K18: =$K$14*I7 -> 57894348
C19: N1 + Roof 2 | D19: =$D$14*D8 -> 59702757 | E19: =$E$14*D8 -> 55737014 | F19: =$F$14*D8 -> 57894348 | H19: N1 + Roof 2 | I19: =$I$14*I8 -> 59702757 | J19: =$J$14*I8 -> 55737014 | K19: =$K$14*I8 -> 57894348
C20: Total Torre 1 | D20: =SUM(D16:D19) -> 2.1358057e+08 | E20: =SUM(E16:E19) -> 1.9939352e+08 | F20: =SUM(F16:F19) -> 2.0711116e+08 | H20: Total Torre 1 | I20: =SUM(I16:I19) -> 2.1358057e+08 | J20: =SUM(J16:J19) -> 1.9939352e+08 | K20: =SUM(K16:K19) -> 2.0711116e+08
C22: USD/M2 | D22: =D14/$D$2 -> 8337.617 | E22: =E14/$D$2 -> 7783.7926 | F22: =F14/$D$2 -> 8085.0688 | H22: USD/M2 | I22: =I14/$D$2 -> 8337.617 | J22: =J14/$D$2 -> 7783.7926 | K22: =K14/$D$2 -> 8085.0688
C24: PB 1 | D24: =D16/$D$2 -> 2690715.7 | E24: =E16/$D$2 -> 2511985.5 | F24: =F16/$D$2 -> 2609213.4 | H24: PB 1 | I24: =I16/$D$2 -> 2690715.7 | J24: =J16/$D$2 -> 2511985.5 | K24: =K16/$D$2 -> 2609213.4
C25: PB 2 | D25: =D17/$D$2 -> 2690715.7 | E25: =E17/$D$2 -> 2511985.5 | F25: =F17/$D$2 -> 2609213.4 | H25: PB 2 | I25: =I17/$D$2 -> 2690715.7 | J25: =J17/$D$2 -> 2511985.5 | K25: =K17/$D$2 -> 2609213.4
C26: N1 + Roof 1 | D26: =D18/$D$2 -> 3411586.1 | E26: =E18/$D$2 -> 3184972.2 | F26: =F18/$D$2 -> 3308248.4 | H26: N1 + Roof 1 | I26: =I18/$D$2 -> 3411586.1 | J26: =J18/$D$2 -> 3184972.2 | K26: =K18/$D$2 -> 3308248.4
C27: N1 + Roof 2 | D27: =D19/$D$2 -> 3411586.1 | E27: =E19/$D$2 -> 3184972.2 | F27: =F19/$D$2 -> 3308248.4 | H27: N1 + Roof 2 | I27: =I19/$D$2 -> 3411586.1 | J27: =J19/$D$2 -> 3184972.2 | K27: =K19/$D$2 -> 3308248.4
C28: Total Torre 1 | D28: =SUM(D24:D27) -> 12204604 | E28: =SUM(E24:E27) -> 11393916 | F28: =SUM(F24:F27) -> 11834924 | H28: Total Torre 1 | I28: =SUM(I24:I27) -> 12204604 | J28: =SUM(J24:J27) -> 11393916 | K28: =SUM(K24:K27) -> 11834924

Sheet PPTO vs PAR
B2: Partidas | D2: Total | E2: % del Total | F2: PPTO | G2: PARAMETRICO | J2: MXN/DEPTO | K2: USD/DEPTO
B3: Obra_Civil | D3: =SUMIFS(Obra_Civil!$T:$T,Obra_Civil!$B:$B,'PPTO vs PAR'!B3) -> 66000000 | E3: =IFERROR(D3/$D$36,0) -> 0.15270544 | F3: =SUMIFS(Obra_Civil!$T:$T,Obra_Civil!$V:$V,'PPTO vs PAR'!F2) -> 33000000 | G3: =SUMIFS(Obra_Civil!$T:$T,Obra_Civil!$V:$V,'PPTO vs PAR'!G2) -> 33000000 | J3: =D3/8 -> 8250000 | K3: =J3/17.5 -> 471428.57
B4: Carpinterias | D4: =SUMIFS(Carpinterias!$U:$U,Carpinterias!$B:$B,'PPTO vs PAR'!B4) -> 46223299 | E4: =IFERROR(D4/$D$36,0) -> 0.10694772 | F4: =SUMIFS(Carpinterias!$U:$U,Carpinterias!$W:$W,F$2) -> 45480899 | G4: =SUMIFS(Carpinterias!$U:$U,Carpinterias!$W:$W,G$2) -> 742400 | J4: =D4/8 -> 5777912.4 | K4: =J4/17.5 -> 330166.42
B5: Automatizacion_Control_Iluminacion | D5: =SUMIFS(Automat_Control_Ilum!$T:$T,Automat_Control_Ilum!$B:$B,'PPTO vs PAR'!B5) -> 19660848 | E5: =IFERROR(D5/$D$36,0) -> 0.045489673 | F5: =SUMIFS(Automat_Control_Ilum!$T:$T,Automat_Control_Ilum!$V:$V,F$2) -> 19660848 | G5: =SUMIFS(Automat_Control_Ilum!$T:$T,Automat_Control_Ilum!$V:$V,G$2) -> 0 | J5: =D5/8 -> 2457605.9 | K5: =J5/17.5 -> 140434.63
B6: Instalaciones_Electricas | D6: =SUMIFS(Instalaciones_Electricas!$T:$T,Instalaciones_Electricas!$B:$B,'PPTO vs PAR'!B6) -> 29733862 | E6: =IFERROR(D6/$D$36,0) -> 0.068795796 | F6: =SUMIFS(Instalaciones_Electricas!$T:$T,Instalaciones_Electricas!$V:$V,F$2) -> 0 | G6: =SUMIFS(Instalaciones_Electricas!$T:$T,Instalaciones_Electricas!$V:$V,G$2) -> 29733862 | J6: =D6/8 -> 3716732.8 | K6: =J6/17.5 -> 212384.73
B7: Vidrios_Y_Canceles | D7: =SUMIFS(Vidrios_Y_Canceles!$T:$T,Vidrios_Y_Canceles!$B:$B,'PPTO vs PAR'!B7) -> 38315914 | E7: =IFERROR(D7/$D$36,0) -> 0.08865225 | F7: =SUMIFS(Vidrios_Y_Canceles!$T:$T,Vidrios_Y_Canceles!$V:$V,F$2) -> 31270607 | G7: =SUMIFS(Vidrios_Y_Canceles!$T:$T,Vidrios_Y_Canceles!$V:$V,G$2) -> 7045306.4 | J7: =D7/8 -> 4789489.2 | K7: =J7/17.5 -> 273685.1
B8: Albercas | D8: =SUMIFS(Albercas!$T:$T,Albercas!$B:$B,'PPTO vs PAR'!B8) -> 23140260 | E8: =IFERROR(D8/$D$36,0) -> 0.053540055 | F8: =SUMIFS(Albercas!$T:$T,Albercas!$V:$V,F$2) -> 23140260 | G8: =SUMIFS(Albercas!$T:$T,Albercas!$V:$V,G$2) -> 0 | J8: =D8/8 -> 2892532.5 | K8: =J8/17.5 -> 165287.57
B9: Exteriores | D9: =SUMIFS(Exteriores!$T:$T,Exteriores!$B:$B,'PPTO vs PAR'!B9) -> 19989130 | E9: =IFERROR(D9/$D$36,0) -> 0.046249226 | F9: =SUMIFS(Exteriores!$T:$T,Exteriores!$V:$V,F$2) -> 0 | G9: =SUMIFS(Exteriores!$T:$T,Exteriores!$V:$V,G$2) -> 19989130 | J9: =D9/8 -> 2498641.2 | K9: =J9/17.5 -> 142779.5
B10: Aire_Acondicionado_Y_Extraccion | D10: =SUMIFS(Aire_Acond_Y_Extraccion!$T:$T,Aire_Acond_Y_Extraccion!$B:$B,'PPTO vs PAR'!B10) -> 15759688 | E10: =IFERROR(D10/$D$36,0) -> 0.036463487 | F10: =SUMIFS(Aire_Acond_Y_Extraccion!$T:$T,Aire_Acond_Y_Extraccion!$V:$V,F$2) -> 15759688 | G10: =SUMIFS(Aire_Acond_Y_Extraccion!$T:$T,Aire_Acond_Y_Extraccion!$V:$V,G$2) -> 0 | J10: =D10/8 -> 1969961 | K10: =J10/17.5 -> 112569.2
B11: Cocinas | D11: =SUMIFS(Cocinas!$U:$U,Cocinas!$B:$B,'PPTO vs PAR'!B11) -> 25879831 | E11: =IFERROR(D11/$D$36,0) -> 0.059878651 | F11: =SUMIFS(Cocinas!$U:$U,Cocinas!$W:$W,F$2) -> 24192991 | G11: =SUMIFS(Cocinas!$U:$U,Cocinas!$W:$W,G$2) -> 1686839.5 | J11: =D11/8 -> 3234978.9 | K11: =J11/17.5 -> 184855.93
B12: Acabados | D12: =SUMIFS(Acabados!$T:$T,Acabados!$B:$B,'PPTO vs PAR'!B12) -> 16880130 | E12: =IFERROR(D12/$D$36,0) -> 0.039055874 | F12: =SUMIFS(Acabados!$T:$T,Acabados!$V:$V,F$2) -> 0 | G12: =SUMIFS(Acabados!$T:$T,Acabados!$V:$V,G$2) -> 16880130 | J12: =D12/8 -> 2110016.2 | K12: =J12/17.5 -> 120572.36
B13: Instalaciones_Hidraulicas | D13: =SUMIFS(Instalaciones_Hidraulicas!$T:$T,Instalaciones_Hidraulicas!$B:$B,'PPTO vs PAR'!B13) -> 16725298 | E13: =IFERROR(D13/$D$36,0) -> 0.038697636 | F13: =SUMIFS(Instalaciones_Hidraulicas!$T:$T,Instalaciones_Hidraulicas!$V:$V,F$2) -> 0 | G13: =SUMIFS(Instalaciones_Hidraulicas!$T:$T,Instalaciones_Hidraulicas!$V:$V,G$2) -> 16725298 | J13: =D13/8 -> 2090662.2 | K13: =J13/17.5 -> 119466.41
B14: Colocacion de Marmol | D14: =SUMIFS(Sumin_Coloc_Marmol!$T:$T,Sumin_Coloc_Marmol!$B:$B,'PPTO vs PAR'!B14) -> 12634103 | E14: =IFERROR(D14/$D$36,0) -> 0.029231761 | F14: =SUMIFS(Sumin_Coloc_Marmol!$T:$T,Sumin_Coloc_Marmol!$B:$B,$B14,Sumin_Coloc_Marmol!$V:$V,F$2) -> 0 | G14: =SUMIFS(Sumin_Coloc_Marmol!$T:$T,Sumin_Coloc_Marmol!$B:$B,$B14,Sumin_Coloc_Marmol!$V:$V,G$2) -> 12634103 | J14: =D14/8 -> 1579262.9 | K14: =J14/17.5 -> 90243.592
B15: Condiciones Generales | D15: =SUMIFS('Condiciones Generales'!$T:$T,'Condiciones Generales'!$B:$B,'PPTO vs PAR'!B15) -> 18600593 | E15: =IFERROR(D15/$D$36,0) -> 0.043036543 | F15: =SUMIFS('Condiciones Generales'!$T:$T,'Condiciones Generales'!$V:$V,F$2) -> 5024417.4 | G15: =SUMIFS('Condiciones Generales'!$T:$T,'Condiciones Generales'!$V:$V,G$2) -> 13576176 | J15: =D15/8 -> 2325074.2 | K15: =J15/17.5 -> 132861.38
B16: Contingencias | D16: =SUMIFS(Contingencias!$T:$T,Contingencias!$B:$B,'PPTO vs PAR'!B16) -> 12000000 | E16: =IFERROR(D16/$D$36,0) -> 0.027764626 | F16: =SUMIFS(Contingencias!$T:$T,Contingencias!$V:$V,F$2) -> 0 | G16: =SUMIFS(Contingencias!$T:$T,Contingencias!$V:$V,G$2) -> 12000000 | J16: =D16/8 -> 1500000 | K16: =J16/17.5 -> 85714.286
B17: Suministro de Marmol | D17: =SUMIFS(Sumin_Coloc_Marmol!$T:$T,Sumin_Coloc_Marmol!$B:$B,'PPTO vs PAR'!B17) -> 8739576.3 | E17: =IFERROR(D17/$D$36,0) -> 0.020220922 | F17: =SUMIFS(Sumin_Coloc_Marmol!$T:$T,Sumin_Coloc_Marmol!$B:$B,$B17,Sumin_Coloc_Marmol!$V:$V,F$2) -> 0 | G17: =SUMIFS(Sumin_Coloc_Marmol!$T:$T,Sumin_Coloc_Marmol!$B:$B,$B17,Sumin_Coloc_Marmol!$V:$V,G$2) -> 8739576.3 | J17: =D17/8 -> 1092447 | K17: =J17/17.5 -> 62425.545
B18: Pilas | D18: =SUMIFS(Pilas!$T:$T,Pilas!$B:$B,'PPTO vs PAR'!B18) -> 8365678.7 | E18: =IFERROR(D18/$D$36,0) -> 0.019355828 | F18: =SUMIFS(Pilas!$T:$T,Pilas!$V:$V,F$2) -> 8365678.7 | G18: =SUMIFS(Pilas!$T:$T,Pilas!$V:$V,G$2) -> 0 | J18: =D18/8 -> 1045709.8 | K18: =J18/17.5 -> 59754.848
B19: Griferia_Y_Accesorios_De_Baño | D19: =SUMIFS(Griferia_Y_Acces_Baño!$T:$T,Griferia_Y_Acces_Baño!$B:$B,'PPTO vs PAR'!B19) -> 8061094.3 | E19: =IFERROR(D19/$D$36,0) -> 0.018651105 | F19: =SUMIFS(Griferia_Y_Acces_Baño!$T:$T,Griferia_Y_Acces_Baño!$V:$V,F$2) -> 8061094.3 | G19: =SUMIFS(Griferia_Y_Acces_Baño!$T:$T,Griferia_Y_Acces_Baño!$V:$V,G$2) -> 0 | J19: =D19/8 -> 1007636.8 | K19: =J19/17.5 -> 57579.245
B20: Jardineria_Y_Riego | D20: =SUMIFS(Jardineria_Y_Riego!$T:$T,Jardineria_Y_Riego!$B:$B,'PPTO vs PAR'!B20) -> 7400800 | E20: =IFERROR(D20/$D$36,0) -> 0.01712337 | F20: =SUMIFS(Jardineria_Y_Riego!$T:$T,Jardineria_Y_Riego!$V:$V,F$2) -> 0 | G20: =SUMIFS(Jardineria_Y_Riego!$T:$T,Jardineria_Y_Riego!$V:$V,G$2) -> 7400800 | J20: =D20/8 -> 925100 | K20: =J20/17.5 -> 52862.857
B21: Iluminacion | D21: =SUMIFS(Iluminacion!$T:$T,Iluminacion!$B:$B,'PPTO vs PAR'!B21) -> 7428736.3 | E21: =IFERROR(D21/$D$36,0) -> 0.017188007 | F21: =SUMIFS(Iluminacion!$T:$T,Iluminacion!$V:$V,F$2) -> 6210736.3 | G21: =SUMIFS(Iluminacion!$T:$T,Iluminacion!$V:$V,G$2) -> 1218000 | J21: =D21/8 -> 928592.04 | K21: =J21/17.5 -> 53062.402
B22: Preliminares | D22: =SUMIFS(Preliminares!$T:$T,Preliminares!$B:$B,'PPTO vs PAR'!B22) -> 1688616.4 | E22: =IFERROR(D22/$D$36,0) -> 0.0039069836 | F22: =SUMIFS(Preliminares!$T:$T,Preliminares!$V:$V,F$2) -> 1688616.4 | G22: =SUMIFS(Preliminares!$T:$T,Preliminares!$V:$V,G$2) -> 0 | J22: =D22/8 -> 211077.05 | K22: =J22/17.5 -> 12061.546
B23: Elevador | D23: =SUMIFS(Elevador!$T:$T,Elevador!$B:$B,'PPTO vs PAR'!B23) -> 3394998.7 | E23: =IFERROR(D23/$D$36,0) -> 0.0078550723 | F23: =SUMIFS(Elevador!$T:$T,Elevador!$V:$V,F$2) -> 0 | G23: =SUMIFS(Elevador!$T:$T,Elevador!$V:$V,G$2) -> 3394998.7 | J23: =D23/8 -> 424374.83 | K23: =J23/17.5 -> 24249.991
B24: Garden and Privacy Walls | D24: =SUMIFS('Garden and Privacy Walls'!$T:$T,'Garden and Privacy Walls'!$B:$B,'PPTO vs PAR'!B24) -> 1192410 | E24: =IFERROR(D24/$D$36,0) -> 0.0027589014 | F24: =SUMIFS('Garden and Privacy Walls'!$T:$T,'Garden and Privacy Walls'!$V:$V,F$2) -> 960409.98 | G24: =SUMIFS('Garden and Privacy Walls'!$T:$T,'Garden and Privacy Walls'!$V:$V,G$2) -> 232000 | J24: =D24/8 -> 149051.25 | K24: =J24/17.5 -> 8517.2141
B25: Herreria | D25: =SUMIFS(Herreria!$T:$T,Herreria!$B:$B,'PPTO vs PAR'!B25) -> 4640000 | E25: =IFERROR(D25/$D$36,0) -> 0.010735655 | F25: =SUMIFS(Herreria!$T:$T,Herreria!$V:$V,F$2) -> 0 | G25: =SUMIFS(Herreria!$T:$T,Herreria!$V:$V,G$2) -> 4640000 | J25: =D25/8 -> 580000 | K25: =J25/17.5 -> 33142.857
B26: Ingenierias_Y_Topografia | D26: =SUMIFS(Ingenierias_Y_Topografia!$T:$T,Ingenierias_Y_Topografia!$B:$B,'PPTO vs PAR'!B26) -> 2229156.1 | E26: =IFERROR(D26/$D$36,0) -> 0.0051576404 | F26: =SUMIFS(Ingenierias_Y_Topografia!$T:$T,Ingenierias_Y_Topografia!$V:$V,F$2) -> 2229156.1 | G26: =SUMIFS(Ingenierias_Y_Topografia!$T:$T,Ingenierias_Y_Topografia!$V:$V,G$2) -> 0 | J26: =D26/8 -> 278644.51 | K26: =J26/17.5 -> 15922.544
B27: Instalaciones_Gas | D27: =SUMIFS(Instalaciones_Gas!$T:$T,Instalaciones_Gas!$B:$B,'PPTO vs PAR'!B27) -> 1856000 | E27: =IFERROR(D27/$D$36,0) -> 0.0042942621 | F27: =SUMIFS(Instalaciones_Gas!$T:$T,Instalaciones_Gas!$V:$V,F$2) -> 0 | G27: =SUMIFS(Instalaciones_Gas!$T:$T,Instalaciones_Gas!$V:$V,G$2) -> 1856000 | J27: =D27/8 -> 232000 | K27: =J27/17.5 -> 13257.143
B28: Impermeabilizacion | D28: =SUMIFS(Impermeabilizacion!$T:$T,Impermeabilizacion!$B:$B,'PPTO vs PAR'!B28) -> 2788215.6 | E28: =IFERROR(D28/$D$36,0) -> 0.0064511468 | F28: =SUMIFS(Impermeabilizacion!$T:$T,Impermeabilizacion!$V:$V,F$2) -> 0 | G28: =SUMIFS(Impermeabilizacion!$T:$T,Impermeabilizacion!$V:$V,G$2) -> 2788215.6 | J28: =D28/8 -> 348526.95 | K28: =J28/17.5 -> 19915.826
B29: Infraestructura | D29: =SUMIFS(Infraestructura!$T:$T,Infraestructura!$B:$B,'PPTO vs PAR'!B29) -> 812000 | E29: =IFERROR(D29/$D$36,0) -> 0.0018787397 | F29: =SUMIFS(Infraestructura!$T:$T,Infraestructura!$V:$V,F$2) -> 0 | G29: =SUMIFS(Infraestructura!$T:$T,Infraestructura!$V:$V,G$2) -> 812000 | J29: =D29/8 -> 101500 | K29: =J29/17.5 -> 5800
B30: Otros | D30: =SUMIFS(Otros!$T:$T,Otros!$B:$B,'PPTO vs PAR'!B30) -> 2640000 | E30: =IFERROR(D30/$D$36,0) -> 0.0061082176 | F30: =SUMIFS(Otros!$T:$T,Otros!$V:$V,F$2) -> 0 | G30: =SUMIFS(Otros!$T:$T,Otros!$V:$V,G$2) -> 2640000 | J30: =D30/8 -> 330000 | K30: =J30/17.5 -> 18857.143
B31: Arquitectura | D31: =SUMIFS(Arquitectura!$T:$T,Arquitectura!$B:$B,'PPTO vs PAR'!B31) -> 2929400 | E31: =IFERROR(D31/$D$36,0) -> 0.0067778079 | F31: =SUMIFS(Arquitectura!$T:$T,Arquitectura!$V:$V,F$2) -> 2929400 | G31: =SUMIFS(Arquitectura!$T:$T,Arquitectura!$V:$V,G$2) -> 0 | J31: =D31/8 -> 366175 | K31: =J31/17.5 -> 20924.286
B32: Excavacion | D32: =SUMIFS(Excavacion!$T:$T,Excavacion!$B:$B,'PPTO vs PAR'!B32) -> 0 | E32: =IFERROR(D32/$D$36,0) -> 0 | F32: =SUMIFS(Excavacion!$T:$T,Excavacion!$V:$V,F$2) -> 0 | G32: =SUMIFS(Excavacion!$T:$T,Excavacion!$V:$V,G$2) -> 0 | J32: =D32/8 -> 0 | K32: =J32/17.5 -> 0
B33: Albañilerias | D33: =SUMIFS('Albañilerias '!$T:$T,'Albañilerias '!$B:$B,'PPTO vs PAR'!B33) -> 6495001.8 | E33: =IFERROR(D33/$D$36,0) -> 0.015027608 | F33: =SUMIFS('Albañilerias '!$T:$T,'Albañilerias '!$V:$V,F$2) -> 3247500.9 | G33: =SUMIFS('Albañilerias '!$T:$T,'Albañilerias '!$V:$V,G$2) -> 3247500.9
B34: Madera_De_Ingenieria | D34: =SUMIFS(Madera_De_Ingenieria!$T:$T,Madera_De_Ingenieria!$B:$B,'PPTO vs PAR'!B34) -> 0 | E34: =IFERROR(D34/$D$36,0) -> 0 | F34: =SUMIFS(Madera_De_Ingenieria!$T$2:$T$61,Madera_De_Ingenieria!$V$2:$V$61,F$2) -> 0 | G34: =SUMIFS(Madera_De_Ingenieria!$T$2:$T$61,Madera_De_Ingenieria!$V$2:$V$61,G$2) -> 0
B36: Total | D36: =SUM(D3:D34) -> 4.3220464e+08 | F36: =SUM(F3:F34) -> 2.312223e+08 | G36: =SUM(G3:G34) -> 2.0098234e+08
D37: =D36-'BUY OUT'!I172 -> 12067000 | F37: =F36/D36 -> 0.53498339 | G37: =G36/D36 -> 0.46501661

Sheet BF vs Golf
B2: Partidas | D2: Total | E2: m2 | F2: $/m2 | H2: GOLF VILLAS | I2: M2 | J2: $/m2
B3: Obra_Civil | D3: =SUMIFS(Obra_Civil!$T:$T,Obra_Civil!$B:$B,'BF vs Golf'!B3) -> 66000000 | E3: 3970 | F3: =IFERROR(D3/E3,0) -> 16624.685 | H3: 6200000 | I3: 633 | J3: =IFERROR(H3/I3,0) -> 9794.6288
B4: Carpinterias | D4: =SUMIFS(Carpinterias!$U:$U,Carpinterias!$B:$B,'BF vs Golf'!B4) -> 46223299 | E4: 3970 | F4: =IFERROR(D4/E4,0) -> 11643.148 | H4: 3298000 | I4: 255 | J4: =IFERROR(H4/I4,0) -> 12933.333
B5: Automatizacion_Control_Iluminacion | D5: =SUMIFS(Automat_Control_Ilum!$T:$T,Automat_Control_Ilum!$B:$B,'BF vs Golf'!B5) -> 19660848 | E5: 5996 | F5: =IFERROR(D5/E5,0) -> 3278.9939 | H5: 585000 | I5: 255 | J5: =IFERROR(H5/I5,0) -> 2294.1176
B6: Instalaciones_Electricas | D6: =SUMIFS(Instalaciones_Electricas!$T:$T,Instalaciones_Electricas!$B:$B,'BF vs Golf'!B6) -> 29733862 | E6: 3970 | F6: =IFERROR(D6/E6,0) -> 7489.6379 | H6: 1718000 | I6: 633 | J6: =IFERROR(H6/I6,0) -> 2714.06
B7: Suministro de Marmol | D7: =SUMIFS(Sumin_Coloc_Marmol!$T:$T,Sumin_Coloc_Marmol!$B:$B,'BF vs Golf'!B7) -> 8739576.3 | E7: 3970 | F7: =IFERROR(D7/E7,0) -> 2201.4046 | H7: 625000 | I7: 633 | J7: =IFERROR(H7/I7,0) -> 987.36177
B8: Colocacion de Marmol | D8: =SUMIFS(Sumin_Coloc_Marmol!$T:$T,Sumin_Coloc_Marmol!$B:$B,'BF vs Golf'!B8) -> 12634103 | E8: 3970 | F8: =IFERROR(D8/E8,0) -> 3182.3937
B9: Albercas | D9: =SUMIFS(Albercas!$T:$T,Albercas!$B:$B,'BF vs Golf'!B9) -> 23140260 | E9: 286 | F9: =IFERROR(D9/E9,0) -> 80910 | H9: 2325000 | I9: 45 | J9: =IFERROR(H9/I9,0) -> 51666.667
B10: Vidrios_Y_Canceles | D10: =SUMIFS(Vidrios_Y_Canceles!$T:$T,Vidrios_Y_Canceles!$B:$B,'BF vs Golf'!B10) -> 38315914 | E10: 3970 | F10: =IFERROR(D10/E10,0) -> 9651.3636 | H10: 2690000 | I10: 633 | J10: =IFERROR(H10/I10,0) -> 4249.6051
B11: Exteriores | D11: =SUMIFS(Exteriores!$T:$T,Exteriores!$B:$B,'BF vs Golf'!B11) -> 19989130 | E11: 3970 | F11: =IFERROR(D11/E11,0) -> 5035.0453 | H11: En infraestructura | I11: =+I9 -> 45 | J11: =IFERROR(H11/I11,0) -> 0
B12: Aire_Acondicionado_Y_Extraccion | D12: =SUMIFS(Aire_Acond_Y_Extraccion!$T:$T,Aire_Acond_Y_Extraccion!$B:$B,'BF vs Golf'!B12) -> 15759688 | E12: 2998 | F12: =IFERROR(D12/E12,0) -> 5256.7339 | H12: 1589000 | I12: 255 | J12: =IFERROR(H12/I12,0) -> 6231.3725
B13: Cocinas | D13: =SUMIFS(Cocinas!$U:$U,Cocinas!$B:$B,'BF vs Golf'!B13) -> 25879831 | E13: 2998 | F13: =IFERROR(D13/E13,0) -> 8632.3652 | H13: 1370000 | I13: 255 | J13: =IFERROR(H13/I13,0) -> 5372.549
B14: Instalaciones_Hidraulicas | D14: =SUMIFS(Instalaciones_Hidraulicas!$T:$T,Instalaciones_Hidraulicas!$B:$B,'BF vs Golf'!B14) -> 16725298 | E14: 3970 | F14: =IFERROR(D14/E14,0) -> 4212.9213 | H14: 972000 | I14: 633 | J14: =IFERROR(H14/I14,0) -> 1535.545
B15: Condiciones Generales | D15: =SUMIFS('Condiciones Generales'!$T:$T,'Condiciones Generales'!$B:$B,'BF vs Golf'!B15) -> 18600593 | E15: 3970 | F15: =IFERROR(D15/E15,0) -> 4685.288
B16: Contingencias | D16: =SUMIFS(Contingencias!$T:$T,Contingencias!$B:$B,'BF vs Golf'!B16) -> 12000000 | E16: 3970 | F16: =IFERROR(D16/E16,0) -> 3022.67
B17: Pilas | D17: =SUMIFS(Pilas!$T:$T,Pilas!$B:$B,'BF vs Golf'!B17) -> 8365678.7 | E17: 2998 | F17: =IFERROR(D17/E17,0) -> 2790.4198 | H17: N/A | I17: 255 | J17: =IFERROR(H17/I17,0) -> 0
B18: Griferia_Y_Accesorios_De_Baño | D18: =SUMIFS(Griferia_Y_Acces_Baño!$T:$T,Griferia_Y_Acces_Baño!$B:$B,'BF vs Golf'!B18) -> 8061094.3 | E18: 2998 | F18: =IFERROR(D18/E18,0) -> 2688.824 | H18: 557000 | I18: 255 | J18: =IFERROR(H18/I18,0) -> 2184.3137
B19: Jardineria_Y_Riego | D19: =SUMIFS(Jardineria_Y_Riego!$T:$T,Jardineria_Y_Riego!$B:$B,'BF vs Golf'!B19) -> 7400800 | E19: 2998 | F19: =IFERROR(D19/E19,0) -> 2468.5791 | H19: En infraestructura | I19: 255 | J19: =IFERROR(H19/I19,0) -> 0
B20: Iluminacion | D20: =SUMIFS(Iluminacion!$T:$T,Iluminacion!$B:$B,'BF vs Golf'!B20) -> 7428736.3 | E20: 3970 | F20: =IFERROR(D20/E20,0) -> 1871.2182 | H20: 321000 | I20: 633 | J20: =IFERROR(H20/I20,0) -> 507.109
B21: Preliminares | D21: =SUMIFS(Preliminares!$T:$T,Preliminares!$B:$B,'BF vs Golf'!B21) -> 1688616.4 | E21: 2998 | F21: =IFERROR(D21/E21,0) -> 563.24764 | H21: En obra civil | I21: 255 | J21: =IFERROR(H21/I21,0) -> 0
B22: Elevador | D22: =SUMIFS(Elevador!$T:$T,Elevador!$B:$B,'BF vs Golf'!B22) -> 3394998.7 | E22: 2998 | F22: =IFERROR(D22/E22,0) -> 1132.4212 | H22: N/A | I22: 255 | J22: =IFERROR(H22/I22,0) -> 0
B23: Garden and Privacy Walls | D23: =SUMIFS('Garden and Privacy Walls'!$T:$T,'Garden and Privacy Walls'!$B:$B,'BF vs Golf'!B23) -> 1192410 | E23: 2998 | F23: =IFERROR(D23/E23,0) -> 397.73515 | H23: N/A | I23: 255 | J23: =IFERROR(H23/I23,0) -> 0
B24: Herreria | D24: =SUMIFS(Herreria!$T:$T,Herreria!$B:$B,'BF vs Golf'!B24) -> 4640000 | E24: 3970 | F24: =IFERROR(D24/E24,0) -> 1168.7657 | H24: 780000 | I24: 633 | J24: =IFERROR(H24/I24,0) -> 1232.2275
B25: Ingenierias_Y_Topografia | D25: =SUMIFS(Ingenierias_Y_Topografia!$T:$T,Ingenierias_Y_Topografia!$B:$B,'BF vs Golf'!B25) -> 2229156.1 | E25: 3970 | F25: =IFERROR(D25/E25,0) -> 561.50028 | H25: 538000 | I25: =+I20 -> 633 | J25: =IFERROR(H25/I25,0) -> 849.92101
B26: Instalaciones_Gas | D26: =SUMIFS(Instalaciones_Gas!$T:$T,Instalaciones_Gas!$B:$B,'BF vs Golf'!B26) -> 1856000 | E26: 3970 | F26: =IFERROR(D26/E26,0) -> 467.5063 | H26: 173000 | I26: =+I20 -> 633 | J26: =IFERROR(H26/I26,0) -> 273.30174
B27: Impermeabilizacion | D27: =SUMIFS(Impermeabilizacion!$T:$T,Impermeabilizacion!$B:$B,'BF vs Golf'!B27) -> 0 | E27: 2998 | F27: =IFERROR(D27/E27,0) -> 0 | H27: En acabados | I27: 255 | J27: =IFERROR(H27/I27,0) -> 0
B28: Infraestructura | D28: =SUMIFS(Infraestructura!$T:$T,Infraestructura!$B:$B,'BF vs Golf'!B28) -> 812000 | E28: 3970 | F28: =IFERROR(D28/E28,0) -> 204.53401 | H28: 7012509.3 | I28: 633 | J28: =IFERROR(H28/I28,0) -> 11078.214
B29: Otros | D29: =SUMIFS(Otros!$T:$T,Otros!$B:$B,'BF vs Golf'!B29) -> 2640000 | E29: 3970 | F29: =IFERROR(D29/E29,0) -> 664.98741
B30: Arquitectura | D30: =SUMIFS(Arquitectura!$T:$T,Arquitectura!$B:$B,'BF vs Golf'!B30) -> 2929400 | E30: 0 | F30: =IFERROR(D30/E30,0) -> 0 | I30: 255 | J30: =IFERROR(H30/I30,0) -> 0
B31: Excavacion | D31: =SUMIFS(Excavacion!$T:$T,Excavacion!$B:$B,'BF vs Golf'!B31) -> 0 | E31: 0 | F31: =IFERROR(D31/E31,0) -> 0 | H31: En obra civil | I31: 0 | J31: =IFERROR(H31/I31,0) -> 0
B32: Albañileria_Y_Bardas | D32: =SUMIFS(#REF!,#REF!,'BF vs Golf'!B32) -> #REF! | E32: 0 | F32: =IFERROR(D32/E32,0) -> 0 | H32: En obra civil | I32: 0 | J32: =IFERROR(H32/I32,0) -> 0
B33: Acabados | D33: =SUMIFS(Acabados!$T:$T,Acabados!$B:$B,'BF vs Golf'!B33) -> 16880130 | E33: 0 | F33: =IFERROR(D33/E33,0) -> 0 | H33: 5095000 | I33: 633 | J33: =IFERROR(H33/I33,0) -> 8048.9731
B34: Madera_De_Ingenieria | D34: =SUMIFS(Madera_De_Ingenieria!$T:$T,Madera_De_Ingenieria!$B:$B,'BF vs Golf'!B34) -> 0 | E34: 0 | F34: =IFERROR(D34/E34,0) -> 0 | H34: N/A | I34: 255 | J34: =IFERROR(H34/I34,0) -> 0
B36: Total | H36: =38000000/255 -> 149019.61

Sheet Glosario Deptos
A1: GLOSARIO DE DEPARTAMENTOS
A3: TORRE | B3: TIPO | C3: PISO(S) | D3: DEPTO | E3: DEPTO (ID ACABADOS) | F3: 5TA RECÁMARA
A4: TORRE 1 | B4: PB | C4: PB | D4: 101 | E4: 101 | F4: NO | G4: 62
A5: TORRE 1 | B5: PB | C5: PB | D5: 201 | E5: 201 | F5: NO | G5: 62
A6: TORRE 1 | B6: Dúplex (N1+N1R) | C6: N1 + N1R | D6: 102 / 103 | E6: 102 (N1) + 103 (N1R) | F6: NO | G6: 72
A7: TORRE 1 | B7: Dúplex (N1+N1R) | C7: N1 + N1R | D7: 202 / 203 | E7: 202 (N1) + 203 (N1R) | F7: NO | G7: 72
A8: TORRE 2 | B8: PB | C8: PB | D8: 301 | E8: 301 | F8: NO | G8: 62
A9: TORRE 2 | B9: PB | C9: PB | D9: 401 | E9: 401 | F9: SÍ | G9: 74
A10: TORRE 2 | B10: Dúplex (N1+N1R) | C10: N1 + N1R | D10: 302 / 303 | E10: 302 (N1) + 303 (N1R) | F10: NO | G10: 72
A11: TORRE 2 | B11: Dúplex (N1+N1R) | C11: N1 + N1R | D11: 402 / 403 | E11: 402 (N1) + 403 (N1R) | F11: SÍ | G11: 82
A13: NOTAS:
A14: • 2 Torres, 4 departamentos por torre (2 PB + 2 Dúplex N1+N1R) = 8 departamentos únicos en total
A15: • Los pisos N1 y N1R corresponden al mismo departamento dúplex (planta baja y planta alta del dúplex)
A16: • En Torre 2, los deptos 401 (PB) y 402/403 (Dúplex) cuentan con quinta recámara
A17: • En Acabados, los deptos dúplex aparecen con IDs separados por piso (ej: 102 en N1 y 103 en N1R)

Sheet Prompt
B10: PROMPT: Consolidar sección en BUY OUT
B12: Consolida la sección [NOMBRE DE SECCIÓN] en la hoja "BUY OUT" en una sola línea de datos, siguiendo este proceso exacto:
B14: Estructura final deseada (4 filas):
B16: Sub-header — fila azul claro (#D9E2F3) con el nombre en mayúsculas, bold
B17: Línea de datos — fondo blanco, una sola fila con:
B18: Col B: Nombre de la categoría (debe coincidir con col B del tab fuente)
B19: Col R: =valorHistorico/2*2 (azul #0000FF) — valor original de PRESUPUESTO BASE sumado de todas las filas de detalle, dividido entre 2 y multiplicado por 2
B20: Col S: =valorHistorico/2*2 (azul #0000FF) — valor original de PPTO MARZO sumado de todas las filas de detalle, dividido entre 2 y multiplicado por 2
B21: Col T: =SUMIFS(TabFuente!$T:$T,TabFuente!$B:$B,$B[fila]&"*") (verde #008000) — SUMIFS dinámico que referencia la celda B en lugar de texto hardcodeado. Usar &"*" wildcard por si hay espacios trailing en el tab fuente
B22: Cols U,V,W,X: Fórmulas derivadas estándar: =IFERROR(T/R-1,0), =S/UNITARIO!$D$9, =R/$D$2, =S/$D$2
B23: SUBTOTAL — fila verde (#E2EFDA), bold, con =SUM() de la fila de datos. Schedule cols (Z
B24: ) también en verde
... B37: Caso especial — dividir en 2 categorías (como Mármol): Si se necesitan 2 líneas (ej: Suministro vs Colocación), para R y S usar la proporción del actual: =totalHistórico * IFERROR(SUMIFS(tab!$T:$T,tab!$B:$B,$B[fila]&"*") / SUM(tab!$T$2:$T$[últimaFilaDatos]),0)⚠️ En el denominador usar rango acotado $T$2:$T$n para excluir la fila "Total" del tab fuente.

Sheet PPT
B3: TORRE 1
B5: RESUMEN | C5: M2 | D5: USD/M2 | E5: USD | G5: USD = 17.5 MXN
B6: M2 PB DEPTO 1 | C6: =SUM($C$17:$C$18) -> 429.44 | D6: =$D$14 -> 485.91924 | E6: =C6*D6 -> 208673.16
B7: M2 PB DEPTO 2 | C7: =SUM($C$17:$C$18) -> 429.44 | D7: =$D$14 -> 485.91924 | E7: =C7*D7 -> 208673.16
B8: M2 N1 + Roof DEPTO 1 | C8: =SUM($D$17:$D$18) -> 563.09 | D8: =$D$14 -> 485.91924 | E8: =C8*D8 -> 273616.26
B9: M2 N1 + Roof DEPTO 2 | C9: =SUM($D$17:$D$18) -> 563.09 | D9: =$D$14 -> 485.91924 | E9: =C9*D9 -> 273616.26
B10: Total Torre 1 | C10: =SUM(C6:C9) -> 1985.06 | D10: =AVERAGE(D6:D9) -> 485.91924 | E10: =SUM(E6:E9) -> 964578.84
B12: COSTO | C12: MXN | D12: USD
B13: Costo Total MXN | C13: ='PPTO vs PAR'!D12 -> 16880130 | D13: =C13/'Glosario Partidas'!$M$9 -> 964578.84
B14: Costo Total M2 | C14: =C13/C10 -> 8503.5867 | D14: =C14/'Glosario Partidas'!$M$9 -> 485.91924
B16: AREAS | C16: PB | D16: N1 y Roof
B17: Area Interior Acondicionado | C17: 322.72 | D17: 409.18
B18: Area Exterior Techada | C18: 106.72 | D18: 153.91
B19: Area Exterior Pavimentada sin Techar | C19: 204.37 | D19: 258.65
B20: Total | C20: =SUM(C17:C19) -> 633.81 | D20: =SUM(D17:D19) -> 821.74
B22: USD M2 | C22: PB | D22: N1 y Roof
B23: Area Interior Acondicionado | C23: =C17*$D$14 -> 156815.86 | D23: =D17*$D$14 -> 198828.43
B24: Area Exterior Techada | C24: =C18*$D$14 -> 51857.301 | D24: =D18*$D$14 -> 74787.83
B25: Area Exterior Pavimentada sin Techar | C25: =C19*$D$14 -> 99307.315 | D25: =D19*$D$14 -> 125683.01
B26: Total | C26: =SUM(C23:C25) -> 307980.47 | D26: =SUM(D23:D25) -> 399299.27
B30: DEPTO | C30: Area Int. Acon. | D30: Area Ext. Techada | E30: Area Exterior Pav. sin Techar | F30: Total m2
B31: PB 1 | C31: 322.72 | D31: 106.72 | E31: 204.37 | F31: 633.81
B32: PB 2 | C32: 322.72 | D32: 106.72 | E32: 204.37 | F32: 633.81
B33: N1 + Roof 1 | C33: 409.18 | D33: 153.91 | E33: 258.65 | F33: 821.74
B34: N1 + Roof 2 | C34: 409.18 | D34: 153.91 | E34: 258.65 | F34: 821.74
B35: Total Torre 1 | C35: 1463.8 | D35: 521.26 | E35: 926.04 | F35: 2911.1
B38: AREA | C38: M2 Totales | D38: Costo Total | E38: USD/M2
B39: Area Int. Acon. | C39: =C35 -> 1463.8 | D39: =$D$13 -> 964578.84 | E39: =D39/C39 -> 658.95535
B40: Area Int. Acon. + Area Ext. Techada | C40: =C35+D35 -> 1985.06 | D40: =$D$13 -> 964578.84 | E40: =D40/C40 -> 485.91924
B41: Area Total | C41: =C40+E35 -> 2911.1 | D41: =$D$13 -> 964578.84 | E41: =D41/C41 -> 331.34514
B45: Comparativa
B47: AREA | C47: Beach Front | D47: Lote 3 | E47: Golf Villas
B48: Area Int. Acon. | C48: =C39 -> 1463.8 | D48: 1225 | E48: 328.06
B49: Area Int. Acon. + Area Ext. Techada | C49: =C40 -> 1985.06 | D49: 1457 | E49: 509.27
B50: Costo Total | C50: =D13 -> 964578.84 | D50: =122259740.143488/19 -> 6434723.2 | E50: =38000000/19 -> 2000000
B52: USD/M2 | C52: Beach Front | D52: Lote 3 | E52: Golf Villas
B53: Area Int. Acon. | C53: =C$50/C48 -> 658.95535 | D53: =D$50/D48 -> 5252.8352 | E53: =E$50/E48 -> 6096.4458
B54: Area Int. Acon. + Area Ext. Techada | C54: =C$50/C49 -> 485.91924 | D54: =D$50/D49 -> 4416.4195 | E54: =E$50/E49 -> 3927.1899
H55: 17.5
B56: Partidas | C56: Beach Front | D56: Lote 3 | E56: Golf Villas | G56: Partidas | H56: Beach Front | I56: Lote 3 | J56: Golf Villas | L56: Partidas | M56: Beach Front | N56: Lote 3 | O56: Golf Villas
...

Sheet BD >>

Sheet BD
B2: DROPDOWN | C2: DROPDOWN | D2: DROPDOWN | G2: INPUT | H2: INPUT | I2: DROPDOWN | J2: INPUT | K2: DROPDOWN | L2: INPUT | M2: NA | O2: NA | Q2: NA | R2: NA | S2: INPUT | T2: NA | U2: INPUT | V2: INPUT
A4: x | B4: CATEGORÍA | C4: CONCEPTO | D4: DETALLE | E4: TORRE | F4: PISO | G4: DEPTO | H4: PROVEEDOR | I4: UNIDAD | J4: CANTIDAD | K4: MONEDA | L4: $ UNITARIO | M4: IMPORTE SIN IVA | N4: SOBRECOSTO | O4: TOTAL SOBRECOSTO | P4: % IVA | Q4: $ IVA | R4: IMPORTE TOTAL | S4: T.C | T4: TOTAL MXN | U4: NOTAS | V4: PARAMETRICO/PPTO
B5: Arquitectura | C5: Diseño Iluminacion | D5: S/D | E5: TORRE 1 | F5: S/D | G5: S/D | H5: NA | I5: Lote | J5: 0 | K5: MXN | L5: 116000 | M5: =J5*L5 -> 0 | N5: 0 | O5: =M5*N5 -> 0 | P5: 0.16 | Q5: =(M5+O5)*P5 -> 0 | R5: =M5+O5+Q5 -> 0 | S5: =INDEX('Glosario Partidas'!$M$8:$M$10,MATCH(BD!K5,'Glosario Partidas'!$L$8:$L$10,0)) -> 1 | T5: =R5*S5 -> 0 | U5: ########### | V5: PARAMETRICO
B6: Arquitectura | C6: Supervision Diseño Iluminacion | D6: S/D | E6: TORRE 1 | F6: S/D | G6: S/D | H6: NA | I6: Lote | J6: 0 | K6: MXN | L6: 0 | M6: =J6*L6 -> 0 | N6: 0 | O6: =M6*N6 -> 0 | P6: 0 | Q6: =(M6+O6)*P6 -> 0 | R6: =M6+O6+Q6 -> 0 | S6: =INDEX('Glosario Partidas'!$M$8:$M$10,MATCH(BD!K6,'Glosario Partidas'!$L$8:$L$10,0)) -> 1 | T6: =R6*S6 -> 0 | U6: ########### | V6: PARAMETRICO
B7: Arquitectura | C7: Diseño Jardineria | D7: S/D | E7: TORRE 1 | F7: S/D | G7: S/D | H7: NA | I7: Lote | J7: 0 | K7: MXN | L7: 180000 | M7: =J7*L7 -> 0 | N7: 0 | O7: =M7*N7 -> 0 | P7: 0.16 | Q7: =(M7+O7)*P7 -> 0 | R7: =M7+O7+Q7 -> 0 | S7: =INDEX('Glosario Partidas'!$M$8:$M$10,MATCH(BD!K7,'Glosario Partidas'!$L$8:$L$10,0)) -> 1 | T7: =R7*S7 -> 0 | U7: ########### | V7: PARAMETRICO
B8: Arquitectura | C8: Supervision Diseño Jardineria | D8: S/D | E8: TORRE 1 | F8: S/D | G8: S/D | H8: NA | I8: Lote | J8: 0 | K8: MXN | L8: 0 | M8: =J8*L8 -> 0 | N8: 0 | O8: =M8*N8 -> 0 | P8: 0 | Q8: =(M8+O8)*P8 -> 0 | R8: =M8+O8+Q8 -> 0 | S8: =INDEX('Glosario Partidas'!$M$8:$M$10,MATCH(BD!K8,'Glosario Partidas'!$L$8:$L$10,0)) -> 1 | T8: =R8*S8 -> 0 | U8: ########### | V8: PARAMETRICO
B9: Ingenierias_Y_Topografia | C9: Topografia Gestoria | D9: S/D | E9: TORRE 1 | F9: S/D | G9: S/D | H9: NA | I9: Lote | J9: 0 | K9: MXN | L9: 0 | M9: =J9*L9 -> 0 | N9: 0 | O9: =M9*N9 -> 0 | P9: 0 | Q9: =(M9+O9)*P9 -> 0 | R9: =M9+O9+Q9 -> 0 | S9: =INDEX('Glosario Partidas'!$M$8:$M$10,MATCH(BD!K9,'Glosario Partidas'!$L$8:$L$10,0)) -> 1 | T9: =R9*S9 -> 0 | U9: ########### | V9: PARAMETRICO
B10: Ingenierias_Y_Topografia | C10: Topografia Obra | D10: S/D | E10: TORRE 1 | F10: S/D | G10: S/D | H10: NA | I10: Semana | J10: 0 | K10: MXN | L10: 0 | M10: =J10*L10 -> 0 | N10: 0 | O10: =M10*N10 -> 0 | P10: 0 | Q10: =(M10+O10)*P10 -> 0 | R10: =M10+O10+Q10 -> 0 | S10: =INDEX('Glosario Partidas'!$M$8:$M$10,MATCH(BD!K10,'Glosario Partidas'!$L$8:$L$10,0)) -> 1 | T10: =R10*S10 -> 0 | U10: ########### | V10: PARAMETRICO
B11: Ingenierias_Y_Topografia | C11: Mecanica De Suelos | D11: S/D | E11: TORRE 1 | F11: S/D | G11: S/D | H11: NA | I11: Lote | J11: 1 | K11: MXN | L11: 156385 | M11: =J11*L11 -> 156385 | N11: 0 | O11: =M11*N11 -> 0 | P11: 0 | Q11: =(M11+O11)*P11 -> 0 | R11: =M11+O11+Q11 -> 156385 | S11: =INDEX('Glosario Partidas'!$M$8:$M$10,MATCH(BD!K11,'Glosario Partidas'!$L$8:$L$10,0)) -> 1 | T11: =R11*S11 -> 156385 | U11: ########### | V11: PPTO
B12: Ingenierias_Y_Topografia | C12: Calculo Estructural | D12: S/D | E12: TORRE 1 | F12: S/D | G12: S/D | H12: NA | I12: Lote | J12: 1 | K12: MXN | L12: 285000 | M12: =J12*L12 -> 285000 | N12: 0 | O12: =M12*N12 -> 0 | P12: 0 | Q12: =(M12+O12)*P12 -> 0 | R12: =M12+O12+Q12 -> 285000 | S12: =INDEX('Glosario Partidas'!$M$8:$M$10,MATCH(BD!K12,'Glosario Partidas'!$L$8:$L$10,0)) -> 1 | T12: =R12*S12 -> 285000 | U12: ########### | V12: PPTO
B13: Ingenierias_Y_Topografia | C13: Diseño Instalaciones. Electricas, Ihs, Alberca, Gas, Etc. | D13: S/D | E13: TORRE 1 | F13: S/D | G13: S/D | H13: NA | I13: Lote | J13: 0 | K13: MXN | L13: 0 | M13: =J13*L13 -> 0 | N13: 0 | O13: =M13*N13 -> 0 | P13: 0 | Q13: =(M13+O13)*P13 -> 0 | R13: =M13+O13+Q13 -> 0 | S13: =INDEX('Glosario Partidas'!$M$8:$M$10,MATCH(BD!K13,'Glosario Partidas'!$L$8:$L$10,0)) -> 1 | T13: =R13*S13 -> 0 | U13: ########### | V13: PARAMETRICO
B14: Indirectos_De_Obra | C14: Trabajos_Preliminares | D14: Despalme | E14: TORRE 1 | F14: S/D | G14: S/D | H14: NA | I14: Lote | J14: 1 | K14: MXN | L14: 58344 | M14: =J14*L14 -> 58344 | N14: 0 | O14: =M14*N14 -> 0 | P14: 0.16 | Q14: =(M14+O14)*P14 -> 9335.04 | R14: =M14+O14+Q14 -> 67679.04 | S14: =INDEX('Glosario Partidas'!$M$8:$M$10,MATCH(BD!K14,'Glosario Partidas'!$L$8:$L$10,0)) -> 1 | T14: =R14*S14 -> 67679.04 | U14: ########### | V14: PPTO
B15: Indirectos_De_Obra | C15: Trabajos_Preliminares | D15: Malla | E15: TORRE 1 | F15: S/D | G15: S/D | H15: NA | I15: Lote | J15: 1 | K15: MXN | L15: 206867.55 | M15: =J15*L15 -> 206867.55 | N15: 0 | O15: =M15*N15 -> 0 | P15: 0.16 | Q15: =(M15+O15)*P15 -> 33098.808 | R15: =M15+O15+Q15 -> 239966.36 | S15: =INDEX('Glosario Partidas'!$M$8:$M$10,MATCH(BD!K15,'Glosario Partidas'!$L$8:$L$10,0)) -> 1 | T15: =R15*S15 -> 239966.36 | U15: ########### | V15: PPTO
B16: Indirectos_De_Obra | C16: Trabajos_Preliminares | D16: Papeleria | E16: TORRE 1 | F16: S/D | G16: S/D | H16: NA | I16: Lote | J16: 1 | K16: MXN | L16: 56815 | M16: =J16*L16 -> 56815 | N16: 0 | O16: =M16*N16 -> 0 | P16: 0.16 | Q16: =(M16+O16)*P16 -> 9090.4 | R16: =M16+O16+Q16 -> 65905.4 | S16: =INDEX('Glosario Partidas'!$M$8:$M$10,MATCH(BD!K16,'Glosario Partidas'!$L$8:$L$10,0)) -> 1 | T16: =R16*S16 -> 65905.4 | U16: ########### | V16: PPTO
B17: Indirectos_De_Obra | C17: Renta Generadores de Luz | D17: Generador 1 | E17: TORRE 1 | F17: S/D | G17: S/D | H17: NA | I17: Lote | J17: 14 | K17: MXN | L17: =33600/2 -> 16800 | M17: =J17*L17 -> 235200 | N17: 0 | O17: =M17*N17 -> 0 | P17: 0.16 | Q17: =(M17+O17)*P17 -> 37632 | R17: =M17+O17+Q17 -> 272832 | S17: =INDEX('Glosario Partidas'!$M$8:$M$10,MATCH(BD!K17,'Glosario Partidas'!$L$8:$L$10,0)) -> 1 | T17: =R17*S17 -> 272832 | U17: ########### | V17: PPTO
B18: Indirectos_De_Obra | C18: Renta Generadores de Luz | D18: Generador 2 | E18: TORRE 1 | F18: S/D | G18: S/D | H18: NA | I18: Lote | J18: 14 | K18: MXN | L18: =33600/2 -> 16800 | M18: =J18*L18 -> 235200 | N18: 0 | O18: =M18*N18 -> 0 | P18: 0.16 | Q18: =(M18+O18)*P18 -> 37632 | R18: =M18+O18+Q18 -> 272832 | S18: =INDEX('Glosario Partidas'!$M$8:$M$10,MATCH(BD!K18,'Glosario Partidas'!$L$8:$L$10,0)) -> 1 | T18: =R18*S18 -> 272832 | U18: ########### | V18: PPTO
B19: Indirectos_De_Obra | C19: Renta Generadores de Luz | D19: Diesel | E19: TORRE 1 | F19: S/D | G19: S/D | H19: NA | I19: Lote | J19: 14 | K19: MXN | L19: 62400 | M19: =J19*L19 -> 873600 | N19: 0 | O19: =M19*N19 -> 0 | P19: 0.16 | Q19: =(M19+O19)*P19 -> 139776 | R19: =M19+O19+Q19 -> 1013376 | S19: =INDEX('Glosario Partidas'!$M$8:$M$10,MATCH(BD!K19,'Glosario Partidas'!$L$8:$L$10,0)) -> 1 | T19: =R19*S19 -> 1013376 | U19: ########### | V19: PARAMETRICO
B20: Indirectos_De_Obra | C20: Renta Generadores de Luz | D20: Operador de Generador | E20: TORRE 1 | F20: S/D | G20: S/D | H20: NA | I20: Lote | J20: 14 | K20: MXN | L20: 20000 | M20: =J20*L20 -> 280000 | N20: 0 | O20: =M20*N20 -> 0 | P20: 0.16 | Q20: =(M20+O20)*P20 -> 44800 | R20: =M20+O20+Q20 -> 324800 | S20: =INDEX('Glosario Partidas'!$M$8:$M$10,MATCH(BD!K20,'Glosario Partidas'!$L$8:$L$10,0)) -> 1 | T20: =R20*S20 -> 324800 | U20: ########### | V20: PARAMETRICO
B21: Indirectos_De_Obra | C21: Renta Camper | D21: S/D | E21: TORRE 1 | F21: S/D | G21: S/D | H21: NA | I21: Mes | J21: 24 | K21: MXN | L21: 24000 | M21: =J21*L21 -> 576000 | N21: 0 | O21: =M21*N21 -> 0 | P21: 0.16 | Q21: =(M21+O21)*P21 -> 92160 | R21: =M21+O21+Q21 -> 668160 | S21: =INDEX('Glosario Partidas'!$M$8:$M$10,MATCH(BD!K21,'Glosario Partidas'!$L$8:$L$10,0)) -> 1 | T21: =R21*S21 -> 668160 | U21: ########### | V21: PARAMETRICO
B22: Indirectos_De_Obra | C22: Auxiliar De Residente ( + 2 Meses ) | D22: S/D | E22: TORRE 1 | F22: S/D | G22: S/D | H22: NA | I22: Mes | J22: 26 | K22: MXN | L22: 45000 | M22: =J22*L22 -> 1170000 | N22: 0 | O22: =M22*N22 -> 0 | P22: 0.16 | Q22: =(M22+O22)*P22 -> 187200 | R22: =M22+O22+Q22 -> 1357200 | S22: =INDEX('Glosario Partidas'!$M$8:$M$10,MATCH(BD!K22,'Glosario Partidas'!$L$8:$L$10,0)) -> 1 | T22: =R22*S22 -> 1357200 | U22: ########### | V22: PARAMETRICO
B23: Indirectos_De_Obra | C23: Honorarios Residente ( + 2 Meses ) | D23: S/D | E23: TORRE 1 | F23: S/D | G23: S/D | H23: NA | I23: Mes | J23: 26 | K23: MXN | L23: 70000 | M23: =J23*L23 -> 1820000 | N23: 0 | O23: =M23*N23 -> 0 | P23: 0.16 | Q23: =(M23+O23)*P23 -> 291200 | R23: =M23+O23+Q23 -> 2111200 | S23: =INDEX('Glosario Partidas'!$M$8:$M$10,MATCH(BD!K23,'Glosario Partidas'!$L$8:$L$10,0)) -> 1 | T23: =R23*S23 -> 2111200 | U23: ########### | V23: PARAMETRICO
B24: Indirectos_De_Obra | C24: Coordinador MEPS | D24: S/D | E24: TORRE 1 | F24: S/D | G24: S/D | H24: NA | I24: Mes | J24: 26 | K24: MXN | L24: 25000 | M24: =J24*L24 -> 650000 | N24: 0 | O24: =M24*N24 -> 0 | P24: 0.16 | Q24: =(M24+O24)*P24 -> 104000 | R24: =M24+O24+Q24 -> 754000 | S24: =INDEX('Glosario Partidas'!$M$8:$M$10,MATCH(BD!K24,'Glosario Partidas'!$L$8:$L$10,0)) -> 1 | T24: =R24*S24 -> 754000 | U24: ########### | V24: PARAMETRICO
B25: Indirectos_De_Obra | C25: Viaticos | D25: S/D | E25: TORRE 1 | F25: S/D | G25: S/D | H25: NA | I25: Mes | J25: 26 | K25: MXN | L25: 60000 | M25: =J25*L25 -> 1560000 | N25: 0 | O25: =M25*N25 -> 0 | P25: 0.16 | Q25: =(M25+O25)*P25 -> 249600 | R25: =M25+O25+Q25 -> 1809600 | S25: =INDEX('Glosario Partidas'!$M$8:$M$10,MATCH(BD!K25,'Glosario Partidas'!$L$8:$L$10,0)) -> 1 | T25: =R25*S25 -> 1809600 | U25: ########### | V25: PARAMETRICO
B26: Indirectos_De_Obra | C26: Mantenimiento Y Limpieza | D26: S/D | E26: TORRE 1 | F26: S/D | G26: S/D | H26: NA | I26: Mes | J26: 14 | K26: MXN | L26: 40000 | M26: =J26*L26 -> 560000 | N26: 0 | O26: =M26*N26 -> 0 | P26: 0.16 | Q26: =(M26+O26)*P26 -> 89600 | R26: =M26+O26+Q26 -> 649600 | S26: =INDEX('Glosario Partidas'!$M$8:$M$10,MATCH(BD!K26,'Glosario Partidas'!$L$8:$L$10,0)) -> 1 | T26: =R26*S26 -> 649600 | U26: ########### | V26: PARAMETRICO
