Workbook

Sheet Configuración
A1: NAUKA
A2: Configuración del Proyecto
A3: Estos valores se usan en la Carátula. Edítalos según el proyecto.
A5: DATOS DEL PROYECTO
A6: # | B6: Campo | C6: Valor
A7: 1 | B7: Nombre del Proyecto | C7: NAUKA
A8: 2 | B8: Ubicación | C8: LOTE 44
A9: 3 | B9: Cliente | C9: NAUKA
A11: FIRMANTES (Aparecen al pie de cada carátula)
A12: # | B12: Nombre | C12: Cargo | D12: Empresa
A13: 1 | B13: Ing. Edy C. Rodriguez | C13: Director De Construcción | D13: IZ Arquitectos
A14: 2 | B14: Arq. Jose Ison | C14: Director General | D14: IZ Arquitectos
A15: 3 | B15: Ing. Marcos Fasja | C15: Director General | D15: GFA
A17: TIP | B17: Para generar una carátula: ve a la hoja "Carátula", elige Contratista y # Estimación en los dropdowns, y presiona Ctrl+P para imprimir/guardar como PDF.

Sheet Carátula
A1: =IF(B2="","NAUKA — SOLICITUD DE PAGO",B2 & IF(B4="",""," — " & B4)) -> ABIKAR — Colocaión cerca perimetral
A2: Propietario: | B2: ABIKAR
A3: Ubicación: | B3: =Configuración!C8 -> LOTE 44 | D3: ESTIMACION
A4: Partida: | B4: Colocaión cerca perimetral | D4: Finiquito
A5: Contrato Total: | B5: =IF(OR(B2="",B4=""),"",IFERROR(SUMIFS(Presupuesto!G:G,Presupuesto!B:B,B2,Presupuesto!C:C,B4),"")) -> 191168
A6: Saldo por Ejercer: | B6: =IF(OR(B2="",B4="",D4=""),"",IFERROR(G10,"")) -> 191168
A7: Fecha: | B7: =IF(OR(B2="",B4="",D4=""),"",IFERROR(SUMIFS('Flujo de Pagos'!C:C,'Flujo de Pagos'!E:E,B2,'Flujo de Pagos'!F:F,B4,'Flujo de Pagos'!H:H,D4),"")) -> 0
A9: ESTIMACION | B9: CATEGORIA | C9: NOMBRE CONTRATISTA | D9: IMPORTE | E9: ACUMULADO | F9: PPTO | G9: POR EJERCER
A10: =IF($B$2="","",$D$4) -> Finiquito | B10: =IF($B$2="","",$B$4) -> Colocaión cerca perimetral | C10: =IF($B$2="","",$B$2) -> ABIKAR | D10: =IF(OR($B$2="",$B$4="",$D$4=""),"",IFERROR(SUMIFS('Flujo de Pagos'!I:I,'Flujo de Pagos'!E:E,$B$2,'Flujo de Pagos'!F:F,$B$4,'Flujo de Pagos'!H:H,$D$4),0)) -> 0 | E10: =IF(OR($B$2="",$B$4="",$D$4=""),"",IFERROR(SUMIFS('Flujo de Pagos'!I:I,'Flujo de Pagos'!E:E,$B$2,'Flujo de Pagos'!F:F,$B$4,'Flujo de Pagos'!C:C,"<="&$B$7),0)) -> 0 | F10: =IF($B$2="","",$B$5) -> 191168 | G10: =IF($B$2="","",IFERROR(F10-E10,0)) -> 191168
A12: TOTAL ESTIMACION | B12: =IF($B$2="","",$B$4) -> Colocaión cerca perimetral | D12: =IF($B$2="","",D10) -> 0
A32: AUTORIZACIONES
B36: FIRMA | D36: FIRMA | F36: FIRMA
B37: =Configuración!B13 -> Ing. Edy C. Rodriguez | D37: =Configuración!B14 -> Arq. Jose Ison | F37: =Configuración!B15 -> Ing. Marcos Fasja
B38: =Configuración!C13 -> Director De Construcción | D38: =Configuración!C14 -> Director General | F38: =Configuración!C15 -> Director General
B39: =Configuración!D13 -> IZ Arquitectos | D39: =Configuración!D14 -> IZ Arquitectos | F39: =Configuración!D15 -> GFA

Sheet Presupuesto
A1: NAUKA
A2: Presupuesto por Contratista
A3: Cifras en MX$
A5: # | B5: CONTRATISTA / PROVEEDOR | C5: PARTIDA | D5: PRESUPUESTO | E5: IVA | F5: IVA | G5: PRESUPUESTO | H5: NOTAS
B6: INPUT | C6: INPUT | D6: INPUT | E6: INPUT | F6: INPUT | G6: INPUT | H6: INPUT
A7: 1 | B7: SAMSTORGAM | C7: Mecanica de Suelos | D7: 183440 | E7: 0.16 | F7: =D7*E7 -> 29350.4 | G7: =D7+F7 -> 212790.4
A8: =A7+1 -> 2 | B8: Hector Triana | C8: Diseño Estructural | D8: 243000 | E8: 0.16 | F8: =D8*E8 -> 38880 | G8: =D8+F8 -> 281880
A9: =A8+1 -> 3 | B9: ABIKAR | C9: Colocaión cerca perimetral | D9: 164800 | E9: 0.16 | F9: =D9*E9 -> 26368 | G9: =D9+F9 -> 191168
A10: =A9+1 -> 4 | B10: Urarq | C10: Derribo y Reubicacion de Arboles | D10: 237891.04 | E10: 0.16 | F10: =D10*E10 -> 38062.566 | G10: =D10+F10 -> 275953.61
A11: =A10+1 -> 5 | B11: Aquaconcepts | C11: Proyecto Alberca y Jacuzzi | D11: 50000 | E11: 0.16 | F11: =D11*E11 -> 8000 | G11: =D11+F11 -> 58000
A12: =A11+1 -> 6
A13: =A12+1 -> 7
A14: =A13+1 -> 8
A15: =A14+1 -> 9
A16: =A15+1 -> 10
A17: =A16+1 -> 11
A18: =A17+1 -> 12
A19: =A18+1 -> 13
A20: =A19+1 -> 14
A21: =A20+1 -> 15
A22: =A21+1 -> 16
A23: =A22+1 -> 17
... A67: =A66+1 -> 61
B68: TOTAL | G68: =SUM(G7:G67) -> 1019792

Sheet Flujo de Pagos
A1: NAUKA
A2: Flujo de Pagos a Contratistas
A3: Cifras en MX$
A5: x | B5: EOM | C5: FECHA DE PAGO | D5: PAGÓ | E5: CONTRATISTA | F5: PARTIDA | G5: CONCEPTO | H5: # ESTIMACION | I5: MONTO | J5: PRESUPUESTO | K5: PAGADO ACUM. | L5: RESTO POR PAGAR | M5: ESTATUS | N5: NOTAS
B6: AUTO | C6: INPUT | D6: DROPDOWN | E6: DROPDOWN | F6: DROPDOWN | G6: INPUT | H6: INPUT | I6: INPUT | J6: AUTO | K6: AUTO | L6: AUTO | M6: DROPDOWN | N6: INPUT
B7: =EOMONTH(C7,0) -> 46053 | C7: 46045 | D7: Salomon Ison | E7: SAMSTORGAM | F7: Mecanica de Suelos | H7: Anticipo | I7: 106395.2 | J7: =IF(OR(E7="",F7=""),"",SUMIFS(Presupuesto!G$7:G$67,Presupuesto!B$7:B$67,E7,Presupuesto!C$7:C$67,F7)) -> 212790.4 | K7: =IF(OR(E7="",F7=""),"",SUMIFS(I$7:I7,E$7:E7,E7,F$7:F7,F7)) -> 106395.2 | L7: =IF(OR(E7="",F7=""),"",J7-SUMIFS(I$7:I$506,E$7:E$506,E7,F$7:F$506,F7)) -> 106395.2 | M7: Pagado
B8: =EOMONTH(C8,0) -> 46081 | C8: 46054 | D8: Salomon Ison | E8: Hector Triana | F8: Diseño Estructural | H8: Anticipo | I8: 100000 | J8: =IF(OR(E8="",F8=""),"",SUMIFS(Presupuesto!G$7:G$67,Presupuesto!B$7:B$67,E8,Presupuesto!C$7:C$67,F8)) -> 281880 | K8: =IF(OR(E8="",F8=""),"",SUMIFS(I$7:I8,E$7:E8,E8,F$7:F8,F8)) -> 100000 | L8: =IF(OR(E8="",F8=""),"",J8-SUMIFS(I$7:I$506,E$7:E$506,E8,F$7:F$506,F8)) -> 181880 | M8: Pagado
B9: =EOMONTH(C9,0) -> 46142 | C9: 46113 | D9: Salomon Ison | E9: ABIKAR | F9: Colocaión cerca perimetral | H9: Anticipo | I9: 90000 | J9: =IF(OR(E9="",F9=""),"",SUMIFS(Presupuesto!G$7:G$67,Presupuesto!B$7:B$67,E9,Presupuesto!C$7:C$67,F9)) -> 191168 | K9: =IF(OR(E9="",F9=""),"",SUMIFS(I$7:I9,E$7:E9,E9,F$7:F9,F9)) -> 90000 | L9: =IF(OR(E9="",F9=""),"",J9-SUMIFS(I$7:I$506,E$7:E$506,E9,F$7:F$506,F9)) -> 101168 | M9: Pagado
B10: =EOMONTH(C10,0) -> 46142 | C10: 46114 | D10: Salomon Ison | E10: Urarq | F10: Derribo y Reubicacion de Arboles | H10: Anticipo | I10: 90000 | J10: =IF(OR(E10="",F10=""),"",SUMIFS(Presupuesto!G$7:G$67,Presupuesto!B$7:B$67,E10,Presupuesto!C$7:C$67,F10)) -> 275953.61 | K10: =IF(OR(E10="",F10=""),"",SUMIFS(I$7:I10,E$7:E10,E10,F$7:F10,F10)) -> 90000 | L10: =IF(OR(E10="",F10=""),"",J10-SUMIFS(I$7:I$506,E$7:E$506,E10,F$7:F$506,F10)) -> 0.7964 | M10: Pagado
B11: =EOMONTH(C11,0) -> 46173 | C11: 46149 | D11: Salomon Ison | E11: Urarq | F11: Derribo y Reubicacion de Arboles | H11: Finiquito | I11: 185952.81 | J11: =IF(OR(E11="",F11=""),"",SUMIFS(Presupuesto!G$7:G$67,Presupuesto!B$7:B$67,E11,Presupuesto!C$7:C$67,F11)) -> 275953.61 | K11: =IF(OR(E11="",F11=""),"",SUMIFS(I$7:I11,E$7:E11,E11,F$7:F11,F11)) -> 275952.81 | L11: =IF(OR(E11="",F11=""),"",J11-SUMIFS(I$7:I$506,E$7:E$506,E11,F$7:F$506,F11)) -> 0.7964 | M11: Pagado
B12: =EOMONTH(C12,0) -> 46173 | C12: 46149 | D12: Salomon Ison | E12: Aquaconcepts | F12: Proyecto Alberca y Jacuzzi | H12: Anticipo | I12: 17400 | J12: =IF(OR(E12="",F12=""),"",SUMIFS(Presupuesto!G$7:G$67,Presupuesto!B$7:B$67,E12,Presupuesto!C$7:C$67,F12)) -> 58000 | K12: =IF(OR(E12="",F12=""),"",SUMIFS(I$7:I12,E$7:E12,E12,F$7:F12,F12)) -> 17400 | L12: =IF(OR(E12="",F12=""),"",J12-SUMIFS(I$7:I$506,E$7:E$506,E12,F$7:F$506,F12)) -> 40600 | M12: Pagado
B13: =EOMONTH(C13,0) -> 1 | J13: =IF(OR(E13="",F13=""),"",SUMIFS(Presupuesto!G$7:G$67,Presupuesto!B$7:B$67,E13,Presupuesto!C$7:C$67,F13)) | K13: =IF(OR(E13="",F13=""),"",SUMIFS(I$7:I13,E$7:E13,E13,F$7:F13,F13)) | L13: =IF(OR(E13="",F13=""),"",J13-SUMIFS(I$7:I$506,E$7:E$506,E13,F$7:F$506,F13))
B14: =EOMONTH(C14,0) -> 1 | J14: =IF(OR(E14="",F14=""),"",SUMIFS(Presupuesto!G$7:G$67,Presupuesto!B$7:B$67,E14,Presupuesto!C$7:C$67,F14)) | K14: =IF(OR(E14="",F14=""),"",SUMIFS(I$7:I14,E$7:E14,E14,F$7:F14,F14)) | L14: =IF(OR(E14="",F14=""),"",J14-SUMIFS(I$7:I$506,E$7:E$506,E14,F$7:F$506,F14))
B15: =EOMONTH(C15,0) -> 1 | J15: =IF(OR(E15="",F15=""),"",SUMIFS(Presupuesto!G$7:G$67,Presupuesto!B$7:B$67,E15,Presupuesto!C$7:C$67,F15)) | K15: =IF(OR(E15="",F15=""),"",SUMIFS(I$7:I15,E$7:E15,E15,F$7:F15,F15)) | L15: =IF(OR(E15="",F15=""),"",J15-SUMIFS(I$7:I$506,E$7:E$506,E15,F$7:F$506,F15))
B16: =EOMONTH(C16,0) -> 1 | J16: =IF(OR(E16="",F16=""),"",SUMIFS(Presupuesto!G$7:G$67,Presupuesto!B$7:B$67,E16,Presupuesto!C$7:C$67,F16)) | K16: =IF(OR(E16="",F16=""),"",SUMIFS(I$7:I16,E$7:E16,E16,F$7:F16,F16)) | L16: =IF(OR(E16="",F16=""),"",J16-SUMIFS(I$7:I$506,E$7:E$506,E16,F$7:F$506,F16))
B17: =EOMONTH(C17,0) -> 1 | J17: =IF(OR(E17="",F17=""),"",SUMIFS(Presupuesto!G$7:G$67,Presupuesto!B$7:B$67,E17,Presupuesto!C$7:C$67,F17)) | K17: =IF(OR(E17="",F17=""),"",SUMIFS(I$7:I17,E$7:E17,E17,F$7:F17,F17)) | L17: =IF(OR(E17="",F17=""),"",J17-SUMIFS(I$7:I$506,E$7:E$506,E17,F$7:F$506,F17))
B18: =EOMONTH(C18,0) -> 1 | J18: =IF(OR(E18="",F18=""),"",SUMIFS(Presupuesto!G$7:G$67,Presupuesto!B$7:B$67,E18,Presupuesto!C$7:C$67,F18)) | K18: =IF(OR(E18="",F18=""),"",SUMIFS(I$7:I18,E$7:E18,E18,F$7:F18,F18)) | L18: =IF(OR(E18="",F18=""),"",J18-SUMIFS(I$7:I$506,E$7:E$506,E18,F$7:F$506,F18))
B19: =EOMONTH(C19,0) -> 1 | J19: =IF(OR(E19="",F19=""),"",SUMIFS(Presupuesto!G$7:G$67,Presupuesto!B$7:B$67,E19,Presupuesto!C$7:C$67,F19)) | K19: =IF(OR(E19="",F19=""),"",SUMIFS(I$7:I19,E$7:E19,E19,F$7:F19,F19)) | L19: =IF(OR(E19="",F19=""),"",J19-SUMIFS(I$7:I$506,E$7:E$506,E19,F$7:F$506,F19))
B20: =EOMONTH(C20,0) -> 1 | J20: =IF(OR(E20="",F20=""),"",SUMIFS(Presupuesto!G$7:G$67,Presupuesto!B$7:B$67,E20,Presupuesto!C$7:C$67,F20)) | K20: =IF(OR(E20="",F20=""),"",SUMIFS(I$7:I20,E$7:E20,E20,F$7:F20,F20)) | L20: =IF(OR(E20="",F20=""),"",J20-SUMIFS(I$7:I$506,E$7:E$506,E20,F$7:F$506,F20))
B21: =EOMONTH(C21,0) -> 1 | J21: =IF(OR(E21="",F21=""),"",SUMIFS(Presupuesto!G$7:G$67,Presupuesto!B$7:B$67,E21,Presupuesto!C$7:C$67,F21)) | K21: =IF(OR(E21="",F21=""),"",SUMIFS(I$7:I21,E$7:E21,E21,F$7:F21,F21)) | L21: =IF(OR(E21="",F21=""),"",J21-SUMIFS(I$7:I$506,E$7:E$506,E21,F$7:F$506,F21))
B22: =EOMONTH(C22,0) -> 1 | J22: =IF(OR(E22="",F22=""),"",SUMIFS(Presupuesto!G$7:G$67,Presupuesto!B$7:B$67,E22,Presupuesto!C$7:C$67,F22)) | K22: =IF(OR(E22="",F22=""),"",SUMIFS(I$7:I22,E$7:E22,E22,F$7:F22,F22)) | L22: =IF(OR(E22="",F22=""),"",J22-SUMIFS(I$7:I$506,E$7:E$506,E22,F$7:F$506,F22))
B23: =EOMONTH(C23,0) -> 1 | J23: =IF(OR(E23="",F23=""),"",SUMIFS(Presupuesto!G$7:G$67,Presupuesto!B$7:B$67,E23,Presupuesto!C$7:C$67,F23)) | K23: =IF(OR(E23="",F23=""),"",SUMIFS(I$7:I23,E$7:E23,E23,F$7:F23,F23)) | L23: =IF(OR(E23="",F23=""),"",J23-SUMIFS(I$7:I$506,E$7:E$506,E23,F$7:F$506,F23))
B24: =EOMONTH(C24,0) -> 1 | J24: =IF(OR(E24="",F24=""),"",SUMIFS(Presupuesto!G$7:G$67,Presupuesto!B$7:B$67,E24,Presupuesto!C$7:C$67,F24)) | K24: =IF(OR(E24="",F24=""),"",SUMIFS(I$7:I24,E$7:E24,E24,F$7:F24,F24)) | L24: =IF(OR(E24="",F24=""),"",J24-SUMIFS(I$7:I$506,E$7:E$506,E24,F$7:F$506,F24))
... B250: =EOMONTH(C250,0) -> 1 | J250: =IF(OR(E250="",F250=""),"",SUMIFS(Presupuesto!G$7:G$67,Presupuesto!B$7:B$67,E250,Presupuesto!C$7:C$67,F250)) | K250: =IF(OR(E250="",F250=""),"",SUMIFS(I$7:I250,E$7:E250,E250,F$7:F250,F250)) | L250: =IF(OR(E250="",F250=""),"",J250-SUMIFS(I$7:I$506,E$7:E$506,E250,F$7:F$506,F250))
B251: =IF(C251="","",DATE(YEAR(C251),MONTH(C251)+1,0)) | J251: =IF(OR(E251="",F251=""),"",SUMIFS(Presupuesto!G$7:G$67,Presupuesto!B$7:B$67,E251,Presupuesto!C$7:C$67,F251)) | K251: =IF(OR(E251="",F251=""),"",SUMIFS(I$7:I251,E$7:E251,E251,F$7:F251,F251)) | L251: =IF(OR(E251="",F251=""),"",J251-SUMIFS(I$7:I$506,E$7:E$506,E251,F$7:F$506,F251))
B252: =IF(C252="","",DATE(YEAR(C252),MONTH(C252)+1,0)) | J252: =IF(OR(E252="",F252=""),"",SUMIFS(Presupuesto!G$7:G$67,Presupuesto!B$7:B$67,E252,Presupuesto!C$7:C$67,F252)) | K252: =IF(OR(E252="",F252=""),"",SUMIFS(I$7:I252,E$7:E252,E252,F$7:F252,F252)) | L252: =IF(OR(E252="",F252=""),"",J252-SUMIFS(I$7:I$506,E$7:E$506,E252,F$7:F$506,F252))
B253: =IF(C253="","",DATE(YEAR(C253),MONTH(C253)+1,0)) | J253: =IF(OR(E253="",F253=""),"",SUMIFS(Presupuesto!G$7:G$67,Presupuesto!B$7:B$67,E253,Presupuesto!C$7:C$67,F253)) | K253: =IF(OR(E253="",F253=""),"",SUMIFS(I$7:I253,E$7:E253,E253,F$7:F253,F253)) | L253: =IF(OR(E253="",F253=""),"",J253-SUMIFS(I$7:I$506,E$7:E$506,E253,F$7:F$506,F253))
B254: =IF(C254="","",DATE(YEAR(C254),MONTH(C254)+1,0)) | J254: =IF(OR(E254="",F254=""),"",SUMIFS(Presupuesto!G$7:G$67,Presupuesto!B$7:B$67,E254,Presupuesto!C$7:C$67,F254)) | K254: =IF(OR(E254="",F254=""),"",SUMIFS(I$7:I254,E$7:E254,E254,F$7:F254,F254)) | L254: =IF(OR(E254="",F254=""),"",J254-SUMIFS(I$7:I$506,E$7:E$506,E254,F$7:F$506,F254))
B255: =IF(C255="","",DATE(YEAR(C255),MONTH(C255)+1,0)) | J255: =IF(OR(E255="",F255=""),"",SUMIFS(Presupuesto!G$7:G$67,Presupuesto!B$7:B$67,E255,Presupuesto!C$7:C$67,F255)) | K255: =IF(OR(E255="",F255=""),"",SUMIFS(I$7:I255,E$7:E255,E255,F$7:F255,F255)) | L255: =IF(OR(E255="",F255=""),"",J255-SUMIFS(I$7:I$506,E$7:E$506,E255,F$7:F$506,F255))
B256: =IF(C256="","",DATE(YEAR(C256),MONTH(C256)+1,0)) | J256: =IF(OR(E256="",F256=""),"",SUMIFS(Presupuesto!G$7:G$67,Presupuesto!B$7:B$67,E256,Presupuesto!C$7:C$67,F256)) | K256: =IF(OR(E256="",F256=""),"",SUMIFS(I$7:I256,E$7:E256,E256,F$7:F256,F256)) | L256: =IF(OR(E256="",F256=""),"",J256-SUMIFS(I$7:I$506,E$7:E$506,E256,F$7:F$506,F256))
B257: =IF(C257="","",DATE(YEAR(C257),MONTH(C257)+1,0)) | J257: =IF(OR(E257="",F257=""),"",SUMIFS(Presupuesto!G$7:G$67,Presupuesto!B$7:B$67,E257,Presupuesto!C$7:C$67,F257)) | K257: =IF(OR(E257="",F257=""),"",SUMIFS(I$7:I257,E$7:E257,E257,F$7:F257,F257)) | L257: =IF(OR(E257="",F257=""),"",J257-SUMIFS(I$7:I$506,E$7:E$506,E257,F$7:F$506,F257))
B258: =IF(C258="","",DATE(YEAR(C258),MONTH(C258)+1,0)) | J258: =IF(OR(E258="",F258=""),"",SUMIFS(Presupuesto!G$7:G$67,Presupuesto!B$7:B$67,E258,Presupuesto!C$7:C$67,F258)) | K258: =IF(OR(E258="",F258=""),"",SUMIFS(I$7:I258,E$7:E258,E258,F$7:F258,F258)) | L258: =IF(OR(E258="",F258=""),"",J258-SUMIFS(I$7:I$506,E$7:E$506,E258,F$7:F$506,F258))
B259: =IF(C259="","",DATE(YEAR(C259),MONTH(C259)+1,0)) | J259: =IF(OR(E259="",F259=""),"",SUMIFS(Presupuesto!G$7:G$67,Presupuesto!B$7:B$67,E259,Presupuesto!C$7:C$67,F259)) | K259: =IF(OR(E259="",F259=""),"",SUMIFS(I$7:I259,E$7:E259,E259,F$7:F259,F259)) | L259: =IF(OR(E259="",F259=""),"",J259-SUMIFS(I$7:I$506,E$7:E$506,E259,F$7:F$506,F259))
B260: =IF(C260="","",DATE(YEAR(C260),MONTH(C260)+1,0)) | J260: =IF(OR(E260="",F260=""),"",SUMIFS(Presupuesto!G$7:G$67,Presupuesto!B$7:B$67,E260,Presupuesto!C$7:C$67,F260)) | K260: =IF(OR(E260="",F260=""),"",SUMIFS(I$7:I260,E$7:E260,E260,F$7:F260,F260)) | L260: =IF(OR(E260="",F260=""),"",J260-SUMIFS(I$7:I$506,E$7:E$506,E260,F$7:F$506,F260))
B261: =IF(C261="","",DATE(YEAR(C261),MONTH(C261)+1,0)) | J261: =IF(OR(E261="",F261=""),"",SUMIFS(Presupuesto!G$7:G$67,Presupuesto!B$7:B$67,E261,Presupuesto!C$7:C$67,F261)) | K261: =IF(OR(E261="",F261=""),"",SUMIFS(I$7:I261,E$7:E261,E261,F$7:F261,F261)) | L261: =IF(OR(E261="",F261=""),"",J261-SUMIFS(I$7:I$506,E$7:E$506,E261,F$7:F$506,F261))
B262: =IF(C262="","",DATE(YEAR(C262),MONTH(C262)+1,0)) | J262: =IF(OR(E262="",F262=""),"",SUMIFS(Presupuesto!G$7:G$67,Presupuesto!B$7:B$67,E262,Presupuesto!C$7:C$67,F262)) | K262: =IF(OR(E262="",F262=""),"",SUMIFS(I$7:I262,E$7:E262,E262,F$7:F262,F262)) | L262: =IF(OR(E262="",F262=""),"",J262-SUMIFS(I$7:I$506,E$7:E$506,E262,F$7:F$506,F262))
... B506: =IF(C506="","",DATE(YEAR(C506),MONTH(C506)+1,0)) | J506: =IF(OR(E506="",F506=""),"",SUMIFS(Presupuesto!G$7:G$67,Presupuesto!B$7:B$67,E506,Presupuesto!C$7:C$67,F506)) | K506: =IF(OR(E506="",F506=""),"",SUMIFS(I$7:I506,E$7:E506,E506,F$7:F506,F506)) | L506: =IF(OR(E506="",F506=""),"",J506-SUMIFS(I$7:I$506,E$7:E$506,E506,F$7:F$506,F506))

Sheet Resumen Total
A1: NAUKA
A2: Resumen por Contratista (Acumulado)
A3: Cifras en MX$
A5: # | B5: CONTRATISTA | C5: PARTIDA | D5: PRESUPUESTO | E5: EJERCIDO | F5: % AVANCE | G5: DISPONIBLE
A6: 1 | B6: =IF(Presupuesto!B7="","",Presupuesto!B7) -> SAMSTORGAM | C6: =IF(Presupuesto!C7="","",Presupuesto!C7) -> Mecanica de Suelos | D6: =IF(Presupuesto!G7="","",Presupuesto!G7) -> 212790.4 | E6: =IF(B6="","",SUMIFS('Flujo de Pagos'!I$7:I$506,'Flujo de Pagos'!E$7:E$506,B6)) -> 106395.2 | F6: =IF(OR(D6="",D6=0),"",E6/D6) -> 0.5 | G6: =IF(D6="","",D6-E6) -> 106395.2
A7: 2 | B7: =IF(Presupuesto!B8="","",Presupuesto!B8) -> Hector Triana | C7: =IF(Presupuesto!C8="","",Presupuesto!C8) -> Diseño Estructural | D7: =IF(Presupuesto!G8="","",Presupuesto!G8) -> 281880 | E7: =IF(B7="","",SUMIFS('Flujo de Pagos'!I$7:I$506,'Flujo de Pagos'!E$7:E$506,B7)) -> 100000 | F7: =IF(OR(D7="",D7=0),"",E7/D7) -> 0.35476089 | G7: =IF(D7="","",D7-E7) -> 181880
A8: 3 | B8: =IF(Presupuesto!B9="","",Presupuesto!B9) -> ABIKAR | C8: =IF(Presupuesto!C9="","",Presupuesto!C9) -> Colocaión cerca perimetral | D8: =IF(Presupuesto!G9="","",Presupuesto!G9) -> 191168 | E8: =IF(B8="","",SUMIFS('Flujo de Pagos'!I$7:I$506,'Flujo de Pagos'!E$7:E$506,B8)) -> 90000 | F8: =IF(OR(D8="",D8=0),"",E8/D8) -> 0.47079009 | G8: =IF(D8="","",D8-E8) -> 101168
A9: 4 | B9: =IF(Presupuesto!B10="","",Presupuesto!B10) -> Urarq | C9: =IF(Presupuesto!C10="","",Presupuesto!C10) -> Derribo y Reubicacion de Arboles | D9: =IF(Presupuesto!G10="","",Presupuesto!G10) -> 275953.61 | E9: =IF(B9="","",SUMIFS('Flujo de Pagos'!I$7:I$506,'Flujo de Pagos'!E$7:E$506,B9)) -> 275952.81 | F9: =IF(OR(D9="",D9=0),"",E9/D9) -> 0.99999711 | G9: =IF(D9="","",D9-E9) -> 0.7964
A10: 5 | B10: =IF(Presupuesto!B11="","",Presupuesto!B11) -> Aquaconcepts | C10: =IF(Presupuesto!C11="","",Presupuesto!C11) -> Proyecto Alberca y Jacuzzi | D10: =IF(Presupuesto!G11="","",Presupuesto!G11) -> 58000 | E10: =IF(B10="","",SUMIFS('Flujo de Pagos'!I$7:I$506,'Flujo de Pagos'!E$7:E$506,B10)) -> 17400 | F10: =IF(OR(D10="",D10=0),"",E10/D10) -> 0.3 | G10: =IF(D10="","",D10-E10) -> 40600
A11: 6 | B11: =IF(Presupuesto!B12="","",Presupuesto!B12) | C11: =IF(Presupuesto!C12="","",Presupuesto!C12) | D11: =IF(Presupuesto!G12="","",Presupuesto!G12) | E11: =IF(B11="","",SUMIFS('Flujo de Pagos'!I$7:I$506,'Flujo de Pagos'!E$7:E$506,B11)) | F11: =IF(OR(D11="",D11=0),"",E11/D11) | G11: =IF(D11="","",D11-E11)
A12: 7 | B12: =IF(Presupuesto!B13="","",Presupuesto!B13) | C12: TOTAL | D12: =SUM(D6:D11) -> 1019792 | E12: =SUM(E6:E11) -> 589748.01 | F12: =IF(OR(D12="",D12=0),"",E12/D12) -> 0.57830225 | G12: =IF(D12="","",D12-E12) -> 430044
A13: 8 | B13: =IF(Presupuesto!B14="","",Presupuesto!B14) | C13: =IF(Presupuesto!C14="","",Presupuesto!C14) | D13: =IF(Presupuesto!G14="","",Presupuesto!G14) | F13: =IF(OR(D13="",D13=0),"",E13/D13) | G13: =IF(D13="","",D13-E13)
A14: 9 | B14: =IF(Presupuesto!B15="","",Presupuesto!B15) | C14: =IF(Presupuesto!C15="","",Presupuesto!C15) | D14: =IF(Presupuesto!G15="","",Presupuesto!G15) | E14: =IF(B14="","",SUMIFS('Flujo de Pagos'!I$7:I$506,'Flujo de Pagos'!E$7:E$506,B14)) | F14: =IF(OR(D14="",D14=0),"",E14/D14) | G14: =IF(D14="","",D14-E14)
A15: 10 | B15: =IF(Presupuesto!B16="","",Presupuesto!B16) | C15: =IF(Presupuesto!C16="","",Presupuesto!C16) | D15: =IF(Presupuesto!G16="","",Presupuesto!G16) | E15: =IF(B15="","",SUMIFS('Flujo de Pagos'!I$7:I$506,'Flujo de Pagos'!E$7:E$506,B15)) | F15: =IF(OR(D15="",D15=0),"",E15/D15) | G15: =IF(D15="","",D15-E15)
A16: 11 | B16: =IF(Presupuesto!B17="","",Presupuesto!B17) | C16: =IF(Presupuesto!C17="","",Presupuesto!C17) | D16: =IF(Presupuesto!G17="","",Presupuesto!G17) | E16: =IF(B16="","",SUMIFS('Flujo de Pagos'!I$7:I$506,'Flujo de Pagos'!E$7:E$506,B16)) | F16: =IF(OR(D16="",D16=0),"",E16/D16) | G16: =IF(D16="","",D16-E16)
A17: 12 | B17: =IF(Presupuesto!B18="","",Presupuesto!B18) | C17: =IF(Presupuesto!C18="","",Presupuesto!C18) | D17: =IF(Presupuesto!G18="","",Presupuesto!G18) | E17: =IF(B17="","",SUMIFS('Flujo de Pagos'!I$7:I$506,'Flujo de Pagos'!E$7:E$506,B17)) | F17: =IF(OR(D17="",D17=0),"",E17/D17) | G17: =IF(D17="","",D17-E17)
A18: 13 | B18: =IF(Presupuesto!B19="","",Presupuesto!B19) | C18: =IF(Presupuesto!C19="","",Presupuesto!C19) | D18: =IF(Presupuesto!G19="","",Presupuesto!G19) | E18: =IF(B18="","",SUMIFS('Flujo de Pagos'!I$7:I$506,'Flujo de Pagos'!E$7:E$506,B18)) | F18: =IF(OR(D18="",D18=0),"",E18/D18) | G18: =IF(D18="","",D18-E18)
A19: 14 | B19: =IF(Presupuesto!B20="","",Presupuesto!B20) | C19: =IF(Presupuesto!C20="","",Presupuesto!C20) | D19: =IF(Presupuesto!G20="","",Presupuesto!G20) | E19: =IF(B19="","",SUMIFS('Flujo de Pagos'!I$7:I$506,'Flujo de Pagos'!E$7:E$506,B19)) | F19: =IF(OR(D19="",D19=0),"",E19/D19) | G19: =IF(D19="","",D19-E19)
A20: 15 | B20: =IF(Presupuesto!B21="","",Presupuesto!B21) | C20: =IF(Presupuesto!C21="","",Presupuesto!C21) | D20: =IF(Presupuesto!G21="","",Presupuesto!G21) | E20: =IF(B20="","",SUMIFS('Flujo de Pagos'!I$7:I$506,'Flujo de Pagos'!E$7:E$506,B20)) | F20: =IF(OR(D20="",D20=0),"",E20/D20) | G20: =IF(D20="","",D20-E20)
A21: 16 | B21: =IF(Presupuesto!B22="","",Presupuesto!B22) | C21: =IF(Presupuesto!C22="","",Presupuesto!C22) | D21: =IF(Presupuesto!G22="","",Presupuesto!G22) | E21: =IF(B21="","",SUMIFS('Flujo de Pagos'!I$7:I$506,'Flujo de Pagos'!E$7:E$506,B21)) | F21: =IF(OR(D21="",D21=0),"",E21/D21) | G21: =IF(D21="","",D21-E21)
A22: 17 | B22: =IF(Presupuesto!B23="","",Presupuesto!B23) | C22: =IF(Presupuesto!C23="","",Presupuesto!C23) | D22: =IF(Presupuesto!G23="","",Presupuesto!G23) | E22: =IF(B22="","",SUMIFS('Flujo de Pagos'!I$7:I$506,'Flujo de Pagos'!E$7:E$506,B22)) | F22: =IF(OR(D22="",D22=0),"",E22/D22) | G22: =IF(D22="","",D22-E22)
A23: 18 | B23: =IF(Presupuesto!B24="","",Presupuesto!B24) | C23: =IF(Presupuesto!C24="","",Presupuesto!C24) | D23: =IF(Presupuesto!G24="","",Presupuesto!G24) | E23: =IF(B23="","",SUMIFS('Flujo de Pagos'!I$7:I$506,'Flujo de Pagos'!E$7:E$506,B23)) | F23: =IF(OR(D23="",D23=0),"",E23/D23) | G23: =IF(D23="","",D23-E23)
A24: 19 | B24: =IF(Presupuesto!B25="","",Presupuesto!B25) | C24: =IF(Presupuesto!C25="","",Presupuesto!C25) | D24: =IF(Presupuesto!G25="","",Presupuesto!G25) | E24: =IF(B24="","",SUMIFS('Flujo de Pagos'!I$7:I$506,'Flujo de Pagos'!E$7:E$506,B24)) | F24: =IF(OR(D24="",D24=0),"",E24/D24) | G24: =IF(D24="","",D24-E24)
A25: 20 | B25: =IF(Presupuesto!B26="","",Presupuesto!B26) | C25: =IF(Presupuesto!C26="","",Presupuesto!C26) | D25: =IF(Presupuesto!G26="","",Presupuesto!G26) | E25: =IF(B25="","",SUMIFS('Flujo de Pagos'!I$7:I$506,'Flujo de Pagos'!E$7:E$506,B25)) | F25: =IF(OR(D25="",D25=0),"",E25/D25) | G25: =IF(D25="","",D25-E25)
... A65: 60 | B65: =IF(Presupuesto!B66="","",Presupuesto!B66) | C65: =IF(Presupuesto!C66="","",Presupuesto!C66) | D65: =IF(Presupuesto!G66="","",Presupuesto!G66) | E65: =IF(B65="","",SUMIFS('Flujo de Pagos'!I$7:I$506,'Flujo de Pagos'!E$7:E$506,B65)) | F65: =IF(OR(D65="",D65=0),"",E65/D65) | G65: =IF(D65="","",D65-E65)
B66: TOTAL | D66: =SUM(D6:D65) -> 2039584 | E66: =SUM(E6:E65) -> 1179496 | F66: =IF(D66=0,"",E66/D66) -> 0.57830225 | G66: =SUM(G6:G65) -> 860087.99

Sheet Resumen Mensual
A1: NAUKA
A2: Resumen mensual de pagos
A3: Cifras en MX$
C6: =YEAR(C7) -> 2026 | D6: =YEAR(D7) -> 2026 | E6: =YEAR(E7) -> 2026 | F6: =YEAR(F7) -> 2026 | G6: =YEAR(G7) -> 2026 | H6: =YEAR(H7) -> 2026 | I6: =YEAR(I7) -> 2026 | J6: =YEAR(J7) -> 2026 | ... AM6: =YEAR(AM7) -> 1899
B7: FLUJO DE PAGOS | C7: 46053 | D7: =EOMONTH(C7,1) -> 46081 | E7: =EOMONTH(D7,1) -> 46112 | F7: =EOMONTH(E7,1) -> 46142 | G7: =EOMONTH(F7,1) -> 46173 | H7: =EOMONTH(G7,1) -> 46203 | I7: =EOMONTH(H7,1) -> 46234 | J7: =EOMONTH(I7,1) -> 46265 | K7: =EOMONTH(J7,1) -> 46295 | ... AL7: =EOMONTH(AK7,1) -> 47118
B9: PAGOS POR CONTRATISTA
B10: =IF(Presupuesto!B7="","",Presupuesto!B7) -> SAMSTORGAM | C10: =IF($B10="","",SUMIFS('Flujo de Pagos'!$I$7:$I$506,'Flujo de Pagos'!$E$7:$E$506,$B10,'Flujo de Pagos'!$B$7:$B$506,C$7)) -> 106395.2 | D10: =IF($B10="","",SUMIFS('Flujo de Pagos'!$I$7:$I$506,'Flujo de Pagos'!$E$7:$E$506,$B10,'Flujo de Pagos'!$B$7:$B$506,D$7)) -> 0 | E10: =IF($B10="","",SUMIFS('Flujo de Pagos'!$I$7:$I$506,'Flujo de Pagos'!$E$7:$E$506,$B10,'Flujo de Pagos'!$B$7:$B$506,E$7)) -> 0 | F10: =IF($B10="","",SUMIFS('Flujo de Pagos'!$I$7:$I$506,'Flujo de Pagos'!$E$7:$E$506,$B10,'Flujo de Pagos'!$B$7:$B$506,F$7)) -> 0 | G10: =IF($B10="","",SUMIFS('Flujo de Pagos'!$I$7:$I$506,'Flujo de Pagos'!$E$7:$E$506,$B10,'Flujo de Pagos'!$B$7:$B$506,G$7)) -> 0 | H10: =IF($B10="","",SUMIFS('Flujo de Pagos'!$I$7:$I$506,'Flujo de Pagos'!$E$7:$E$506,$B10,'Flujo de Pagos'!$B$7:$B$506,H$7)) -> 0 | I10: =IF($B10="","",SUMIFS('Flujo de Pagos'!$I$7:$I$506,'Flujo de Pagos'!$E$7:$E$506,$B10,'Flujo de Pagos'!$B$7:$B$506,I$7)) -> 0 | J10: =IF($B10="","",SUMIFS('Flujo de Pagos'!$I$7:$I$506,'Flujo de Pagos'!$E$7:$E$506,$B10,'Flujo de Pagos'!$B$7:$B$506,J$7)) -> 0 | ... AL10: =IF($B10="","",SUMIFS('Flujo de Pagos'!$I$7:$I$506,'Flujo de Pagos'!$E$7:$E$506,$B10,'Flujo de Pagos'!$B$7:$B$506,AL$7)) -> 0 | AM10: =SUM(C10:AL10) -> 106395.2
B11: =IF(Presupuesto!B8="","",Presupuesto!B8) -> Hector Triana | C11: =IF($B11="","",SUMIFS('Flujo de Pagos'!$I$7:$I$506,'Flujo de Pagos'!$E$7:$E$506,$B11,'Flujo de Pagos'!$B$7:$B$506,C$7)) -> 0 | D11: =IF($B11="","",SUMIFS('Flujo de Pagos'!$I$7:$I$506,'Flujo de Pagos'!$E$7:$E$506,$B11,'Flujo de Pagos'!$B$7:$B$506,D$7)) -> 100000 | E11: =IF($B11="","",SUMIFS('Flujo de Pagos'!$I$7:$I$506,'Flujo de Pagos'!$E$7:$E$506,$B11,'Flujo de Pagos'!$B$7:$B$506,E$7)) -> 0 | F11: =IF($B11="","",SUMIFS('Flujo de Pagos'!$I$7:$I$506,'Flujo de Pagos'!$E$7:$E$506,$B11,'Flujo de Pagos'!$B$7:$B$506,F$7)) -> 0 | G11: =IF($B11="","",SUMIFS('Flujo de Pagos'!$I$7:$I$506,'Flujo de Pagos'!$E$7:$E$506,$B11,'Flujo de Pagos'!$B$7:$B$506,G$7)) -> 0 | H11: =IF($B11="","",SUMIFS('Flujo de Pagos'!$I$7:$I$506,'Flujo de Pagos'!$E$7:$E$506,$B11,'Flujo de Pagos'!$B$7:$B$506,H$7)) -> 0 | I11: =IF($B11="","",SUMIFS('Flujo de Pagos'!$I$7:$I$506,'Flujo de Pagos'!$E$7:$E$506,$B11,'Flujo de Pagos'!$B$7:$B$506,I$7)) -> 0 | J11: =IF($B11="","",SUMIFS('Flujo de Pagos'!$I$7:$I$506,'Flujo de Pagos'!$E$7:$E$506,$B11,'Flujo de Pagos'!$B$7:$B$506,J$7)) -> 0 | ... AL11: =IF($B11="","",SUMIFS('Flujo de Pagos'!$I$7:$I$506,'Flujo de Pagos'!$E$7:$E$506,$B11,'Flujo de Pagos'!$B$7:$B$506,AL$7)) -> 0 | AM11: =SUM(C11:AL11) -> 100000
B12: =IF(Presupuesto!B9="","",Presupuesto!B9) -> ABIKAR | C12: =IF($B12="","",SUMIFS('Flujo de Pagos'!$I$7:$I$506,'Flujo de Pagos'!$E$7:$E$506,$B12,'Flujo de Pagos'!$B$7:$B$506,C$7)) -> 0 | D12: =IF($B12="","",SUMIFS('Flujo de Pagos'!$I$7:$I$506,'Flujo de Pagos'!$E$7:$E$506,$B12,'Flujo de Pagos'!$B$7:$B$506,D$7)) -> 0 | E12: =IF($B12="","",SUMIFS('Flujo de Pagos'!$I$7:$I$506,'Flujo de Pagos'!$E$7:$E$506,$B12,'Flujo de Pagos'!$B$7:$B$506,E$7)) -> 0 | F12: =IF($B12="","",SUMIFS('Flujo de Pagos'!$I$7:$I$506,'Flujo de Pagos'!$E$7:$E$506,$B12,'Flujo de Pagos'!$B$7:$B$506,F$7)) -> 90000 | G12: =IF($B12="","",SUMIFS('Flujo de Pagos'!$I$7:$I$506,'Flujo de Pagos'!$E$7:$E$506,$B12,'Flujo de Pagos'!$B$7:$B$506,G$7)) -> 0 | H12: =IF($B12="","",SUMIFS('Flujo de Pagos'!$I$7:$I$506,'Flujo de Pagos'!$E$7:$E$506,$B12,'Flujo de Pagos'!$B$7:$B$506,H$7)) -> 0 | I12: =IF($B12="","",SUMIFS('Flujo de Pagos'!$I$7:$I$506,'Flujo de Pagos'!$E$7:$E$506,$B12,'Flujo de Pagos'!$B$7:$B$506,I$7)) -> 0 | J12: =IF($B12="","",SUMIFS('Flujo de Pagos'!$I$7:$I$506,'Flujo de Pagos'!$E$7:$E$506,$B12,'Flujo de Pagos'!$B$7:$B$506,J$7)) -> 0 | ... AL12: =IF($B12="","",SUMIFS('Flujo de Pagos'!$I$7:$I$506,'Flujo de Pagos'!$E$7:$E$506,$B12,'Flujo de Pagos'!$B$7:$B$506,AL$7)) -> 0 | AM12: =SUM(C12:AL12) -> 90000
B13: =IF(Presupuesto!B10="","",Presupuesto!B10) -> Urarq | C13: =IF($B13="","",SUMIFS('Flujo de Pagos'!$I$7:$I$506,'Flujo de Pagos'!$E$7:$E$506,$B13,'Flujo de Pagos'!$B$7:$B$506,C$7)) -> 0 | D13: =IF($B13="","",SUMIFS('Flujo de Pagos'!$I$7:$I$506,'Flujo de Pagos'!$E$7:$E$506,$B13,'Flujo de Pagos'!$B$7:$B$506,D$7)) -> 0 | E13: =IF($B13="","",SUMIFS('Flujo de Pagos'!$I$7:$I$506,'Flujo de Pagos'!$E$7:$E$506,$B13,'Flujo de Pagos'!$B$7:$B$506,E$7)) -> 0 | F13: =IF($B13="","",SUMIFS('Flujo de Pagos'!$I$7:$I$506,'Flujo de Pagos'!$E$7:$E$506,$B13,'Flujo de Pagos'!$B$7:$B$506,F$7)) -> 90000 | G13: =IF($B13="","",SUMIFS('Flujo de Pagos'!$I$7:$I$506,'Flujo de Pagos'!$E$7:$E$506,$B13,'Flujo de Pagos'!$B$7:$B$506,G$7)) -> 185952.81 | H13: =IF($B13="","",SUMIFS('Flujo de Pagos'!$I$7:$I$506,'Flujo de Pagos'!$E$7:$E$506,$B13,'Flujo de Pagos'!$B$7:$B$506,H$7)) -> 0 | I13: =IF($B13="","",SUMIFS('Flujo de Pagos'!$I$7:$I$506,'Flujo de Pagos'!$E$7:$E$506,$B13,'Flujo de Pagos'!$B$7:$B$506,I$7)) -> 0 | J13: =IF($B13="","",SUMIFS('Flujo de Pagos'!$I$7:$I$506,'Flujo de Pagos'!$E$7:$E$506,$B13,'Flujo de Pagos'!$B$7:$B$506,J$7)) -> 0 | ... AL13: =IF($B13="","",SUMIFS('Flujo de Pagos'!$I$7:$I$506,'Flujo de Pagos'!$E$7:$E$506,$B13,'Flujo de Pagos'!$B$7:$B$506,AL$7)) -> 0 | AM13: =SUM(C13:AL13) -> 275952.81
B14: =IF(Presupuesto!B11="","",Presupuesto!B11) -> Aquaconcepts | C14: =IF(B14="","",SUMIFS('Flujo de Pagos'!I$7:I$506,'Flujo de Pagos'!E$7:E$506,B14,'Flujo de Pagos'!B$7:B$506,C7)) -> 0 | D14: =IF(B14="","",SUMIFS('Flujo de Pagos'!I$7:I$506,'Flujo de Pagos'!E$7:E$506,B14,'Flujo de Pagos'!B$7:B$506,D7)) -> 0 | E14: =IF(B14="","",SUMIFS('Flujo de Pagos'!I$7:I$506,'Flujo de Pagos'!E$7:E$506,B14,'Flujo de Pagos'!B$7:B$506,E7)) -> 0 | F14: =IF(B14="","",SUMIFS('Flujo de Pagos'!I$7:I$506,'Flujo de Pagos'!E$7:E$506,B14,'Flujo de Pagos'!B$7:B$506,F7)) -> 0 | G14: =IF(B14="","",SUMIFS('Flujo de Pagos'!I$7:I$506,'Flujo de Pagos'!E$7:E$506,B14,'Flujo de Pagos'!B$7:B$506,G7)) -> 17400 | H14: =IF(B14="","",SUMIFS('Flujo de Pagos'!I$7:I$506,'Flujo de Pagos'!E$7:E$506,B14,'Flujo de Pagos'!B$7:B$506,H7)) -> 0 | I14: =IF(B14="","",SUMIFS('Flujo de Pagos'!I$7:I$506,'Flujo de Pagos'!E$7:E$506,B14,'Flujo de Pagos'!B$7:B$506,I7)) -> 0 | J14: =IF(B14="","",SUMIFS('Flujo de Pagos'!I$7:I$506,'Flujo de Pagos'!E$7:E$506,B14,'Flujo de Pagos'!B$7:B$506,J7)) -> 0 | K14: =IF(B14="","",SUMIFS('Flujo de Pagos'!I$7:I$506,'Flujo de Pagos'!E$7:E$506,B14,'Flujo de Pagos'!B$7:B$506,K7)) -> 0 | L14: =IF(B14="","",SUMIFS('Flujo de Pagos'!I$7:I$506,'Flujo de Pagos'!E$7:E$506,B14,'Flujo de Pagos'!B$7:B$506,L7)) -> 0 | M14: =IF(B14="","",SUMIFS('Flujo de Pagos'!I$7:I$506,'Flujo de Pagos'!E$7:E$506,B14,'Flujo de Pagos'!B$7:B$506,M7)) -> 0 | N14: =IF(B14="","",SUMIFS('Flujo de Pagos'!I$7:I$506,'Flujo de Pagos'!E$7:E$506,B14,'Flujo de Pagos'!B$7:B$506,N7)) -> 0 | O14: =IF(B14="","",SUMIFS('Flujo de Pagos'!I$7:I$506,'Flujo de Pagos'!E$7:E$506,B14,'Flujo de Pagos'!B$7:B$506,O7)) -> 0 | P14: =IF(B14="","",SUMIFS('Flujo de Pagos'!I$7:I$506,'Flujo de Pagos'!E$7:E$506,B14,'Flujo de Pagos'!B$7:B$506,P7)) -> 0 | Q14: =IF(B14="","",SUMIFS('Flujo de Pagos'!I$7:I$506,'Flujo de Pagos'!E$7:E$506,B14,'Flujo de Pagos'!B$7:B$506,Q7)) -> 0 | R14: =IF(B14="","",SUMIFS('Flujo de Pagos'!I$7:I$506,'Flujo de Pagos'!E$7:E$506,B14,'Flujo de Pagos'!B$7:B$506,R7)) -> 0 | S14: =IF(B14="","",SUMIFS('Flujo de Pagos'!I$7:I$506,'Flujo de Pagos'!E$7:E$506,B14,'Flujo de Pagos'!B$7:B$506,S7)) -> 0 | T14: =IF(B14="","",SUMIFS('Flujo de Pagos'!I$7:I$506,'Flujo de Pagos'!E$7:E$506,B14,'Flujo de Pagos'!B$7:B$506,T7)) -> 0 | U14: =IF(B14="","",SUMIFS('Flujo de Pagos'!I$7:I$506,'Flujo de Pagos'!E$7:E$506,B14,'Flujo de Pagos'!B$7:B$506,U7)) -> 0 | V14: =IF(B14="","",SUMIFS('Flujo de Pagos'!I$7:I$506,'Flujo de Pagos'!E$7:E$506,B14,'Flujo de Pagos'!B$7:B$506,V7)) -> 0 | W14: =IF(B14="","",SUMIFS('Flujo de Pagos'!I$7:I$506,'Flujo de Pagos'!E$7:E$506,B14,'Flujo de Pagos'!B$7:B$506,W7)) -> 0 | X14: =IF(B14="","",SUMIFS('Flujo de Pagos'!I$7:I$506,'Flujo de Pagos'!E$7:E$506,B14,'Flujo de Pagos'!B$7:B$506,X7)) -> 0 | Y14: =IF(B14="","",SUMIFS('Flujo de Pagos'!I$7:I$506,'Flujo de Pagos'!E$7:E$506,B14,'Flujo de Pagos'!B$7:B$506,Y7)) -> 0 | Z14: =IF(B14="","",SUMIFS('Flujo de Pagos'!I$7:I$506,'Flujo de Pagos'!E$7:E$506,B14,'Flujo de Pagos'!B$7:B$506,Z7)) -> 0 | AA14: =IF(B14="","",SUMIFS('Flujo de Pagos'!I$7:I$506,'Flujo de Pagos'!E$7:E$506,B14,'Flujo de Pagos'!B$7:B$506,AA7)) -> 0 | AB14: =IF(B14="","",SUMIFS('Flujo de Pagos'!I$7:I$506,'Flujo de Pagos'!E$7:E$506,B14,'Flujo de Pagos'!B$7:B$506,AB7)) -> 0 | AC14: =IF(B14="","",SUMIFS('Flujo de Pagos'!I$7:I$506,'Flujo de Pagos'!E$7:E$506,B14,'Flujo de Pagos'!B$7:B$506,AC7)) -> 0 | AD14: =IF(B14="","",SUMIFS('Flujo de Pagos'!I$7:I$506,'Flujo de Pagos'!E$7:E$506,B14,'Flujo de Pagos'!B$7:B$506,AD7)) -> 0 | AE14: =IF(B14="","",SUMIFS('Flujo de Pagos'!I$7:I$506,'Flujo de Pagos'!E$7:E$506,B14,'Flujo de Pagos'!B$7:B$506,AE7)) -> 0 | AF14: =IF(B14="","",SUMIFS('Flujo de Pagos'!I$7:I$506,'Flujo de Pagos'!E$7:E$506,B14,'Flujo de Pagos'!B$7:B$506,AF7)) -> 0 | AG14: =IF(B14="","",SUMIFS('Flujo de Pagos'!I$7:I$506,'Flujo de Pagos'!E$7:E$506,B14,'Flujo de Pagos'!B$7:B$506,AG7)) -> 0 | AH14: =IF(B14="","",SUMIFS('Flujo de Pagos'!I$7:I$506,'Flujo de Pagos'!E$7:E$506,B14,'Flujo de Pagos'!B$7:B$506,AH7)) -> 0 | AI14: =IF(B14="","",SUMIFS('Flujo de Pagos'!I$7:I$506,'Flujo de Pagos'!E$7:E$506,B14,'Flujo de Pagos'!B$7:B$506,AI7)) -> 0 | AJ14: =IF(B14="","",SUMIFS('Flujo de Pagos'!I$7:I$506,'Flujo de Pagos'!E$7:E$506,B14,'Flujo de Pagos'!B$7:B$506,AJ7)) -> 0 | AK14: =IF(B14="","",SUMIFS('Flujo de Pagos'!I$7:I$506,'Flujo de Pagos'!E$7:E$506,B14,'Flujo de Pagos'!B$7:B$506,AK7)) -> 0 | AL14: =IF(B14="","",SUMIFS('Flujo de Pagos'!I$7:I$506,'Flujo de Pagos'!E$7:E$506,B14,'Flujo de Pagos'!B$7:B$506,AL7)) -> 0 | AM14: =IF(B14="","",SUM(C14:AL14)) -> 17400
B15: =IF(Presupuesto!B12="","",Presupuesto!B12) | C15: =IF(B15="","",SUMIFS('Flujo de Pagos'!I$7:I$506,'Flujo de Pagos'!E$7:E$506,B15,'Flujo de Pagos'!B$7:B$506,C7)) | D15: =IF(B15="","",SUMIFS('Flujo de Pagos'!I$7:I$506,'Flujo de Pagos'!E$7:E$506,B15,'Flujo de Pagos'!B$7:B$506,D7)) | E15: =IF(B15="","",SUMIFS('Flujo de Pagos'!I$7:I$506,'Flujo de Pagos'!E$7:E$506,B15,'Flujo de Pagos'!B$7:B$506,E7)) | F15: =IF(B15="","",SUMIFS('Flujo de Pagos'!I$7:I$506,'Flujo de Pagos'!E$7:E$506,B15,'Flujo de Pagos'!B$7:B$506,F7)) | G15: =IF(B15="","",SUMIFS('Flujo de Pagos'!I$7:I$506,'Flujo de Pagos'!E$7:E$506,B15,'Flujo de Pagos'!B$7:B$506,G7)) | H15: =IF(B15="","",SUMIFS('Flujo de Pagos'!I$7:I$506,'Flujo de Pagos'!E$7:E$506,B15,'Flujo de Pagos'!B$7:B$506,H7)) | I15: =IF(B15="","",SUMIFS('Flujo de Pagos'!I$7:I$506,'Flujo de Pagos'!E$7:E$506,B15,'Flujo de Pagos'!B$7:B$506,I7)) | J15: =IF(B15="","",SUMIFS('Flujo de Pagos'!I$7:I$506,'Flujo de Pagos'!E$7:E$506,B15,'Flujo de Pagos'!B$7:B$506,J7)) | K15: =IF(B15="","",SUMIFS('Flujo de Pagos'!I$7:I$506,'Flujo de Pagos'!E$7:E$506,B15,'Flujo de Pagos'!B$7:B$506,K7)) | L15: =IF(B15="","",SUMIFS('Flujo de Pagos'!I$7:I$506,'Flujo de Pagos'!E$7:E$506,B15,'Flujo de Pagos'!B$7:B$506,L7)) | M15: =IF(B15="","",SUMIFS('Flujo de Pagos'!I$7:I$506,'Flujo de Pagos'!E$7:E$506,B15,'Flujo de Pagos'!B$7:B$506,M7)) | N15: =IF(B15="","",SUMIFS('Flujo de Pagos'!I$7:I$506,'Flujo de Pagos'!E$7:E$506,B15,'Flujo de Pagos'!B$7:B$506,N7)) | O15: =IF(B15="","",SUMIFS('Flujo de Pagos'!I$7:I$506,'Flujo de Pagos'!E$7:E$506,B15,'Flujo de Pagos'!B$7:B$506,O7)) | P15: =IF(B15="","",SUMIFS('Flujo de Pagos'!I$7:I$506,'Flujo de Pagos'!E$7:E$506,B15,'Flujo de Pagos'!B$7:B$506,P7)) | Q15: =IF(B15="","",SUMIFS('Flujo de Pagos'!I$7:I$506,'Flujo de Pagos'!E$7:E$506,B15,'Flujo de Pagos'!B$7:B$506,Q7)) | R15: =IF(B15="","",SUMIFS('Flujo de Pagos'!I$7:I$506,'Flujo de Pagos'!E$7:E$506,B15,'Flujo de Pagos'!B$7:B$506,R7)) | S15: =IF(B15="","",SUMIFS('Flujo de Pagos'!I$7:I$506,'Flujo de Pagos'!E$7:E$506,B15,'Flujo de Pagos'!B$7:B$506,S7)) | T15: =IF(B15="","",SUMIFS('Flujo de Pagos'!I$7:I$506,'Flujo de Pagos'!E$7:E$506,B15,'Flujo de Pagos'!B$7:B$506,T7)) | U15: =IF(B15="","",SUMIFS('Flujo de Pagos'!I$7:I$506,'Flujo de Pagos'!E$7:E$506,B15,'Flujo de Pagos'!B$7:B$506,U7)) | V15: =IF(B15="","",SUMIFS('Flujo de Pagos'!I$7:I$506,'Flujo de Pagos'!E$7:E$506,B15,'Flujo de Pagos'!B$7:B$506,V7)) | W15: =IF(B15="","",SUMIFS('Flujo de Pagos'!I$7:I$506,'Flujo de Pagos'!E$7:E$506,B15,'Flujo de Pagos'!B$7:B$506,W7)) | X15: =IF(B15="","",SUMIFS('Flujo de Pagos'!I$7:I$506,'Flujo de Pagos'!E$7:E$506,B15,'Flujo de Pagos'!B$7:B$506,X7)) | Y15: =IF(B15="","",SUMIFS('Flujo de Pagos'!I$7:I$506,'Flujo de Pagos'!E$7:E$506,B15,'Flujo de Pagos'!B$7:B$506,Y7)) | Z15: =IF(B15="","",SUMIFS('Flujo de Pagos'!I$7:I$506,'Flujo de Pagos'!E$7:E$506,B15,'Flujo de Pagos'!B$7:B$506,Z7)) | AA15: =IF(B15="","",SUMIFS('Flujo de Pagos'!I$7:I$506,'Flujo de Pagos'!E$7:E$506,B15,'Flujo de Pagos'!B$7:B$506,AA7)) | AB15: =IF(B15="","",SUMIFS('Flujo de Pagos'!I$7:I$506,'Flujo de Pagos'!E$7:E$506,B15,'Flujo de Pagos'!B$7:B$506,AB7)) | AC15: =IF(B15="","",SUMIFS('Flujo de Pagos'!I$7:I$506,'Flujo de Pagos'!E$7:E$506,B15,'Flujo de Pagos'!B$7:B$506,AC7)) | AD15: =IF(B15="","",SUMIFS('Flujo de Pagos'!I$7:I$506,'Flujo de Pagos'!E$7:E$506,B15,'Flujo de Pagos'!B$7:B$506,AD7)) | AE15: =IF(B15="","",SUMIFS('Flujo de Pagos'!I$7:I$506,'Flujo de Pagos'!E$7:E$506,B15,'Flujo de Pagos'!B$7:B$506,AE7)) | AF15: =IF(B15="","",SUMIFS('Flujo de Pagos'!I$7:I$506,'Flujo de Pagos'!E$7:E$506,B15,'Flujo de Pagos'!B$7:B$506,AF7)) | AG15: =IF(B15="","",SUMIFS('Flujo de Pagos'!I$7:I$506,'Flujo de Pagos'!E$7:E$506,B15,'Flujo de Pagos'!B$7:B$506,AG7)) | AH15: =IF(B15="","",SUMIFS('Flujo de Pagos'!I$7:I$506,'Flujo de Pagos'!E$7:E$506,B15,'Flujo de Pagos'!B$7:B$506,AH7)) | AI15: =IF(B15="","",SUMIFS('Flujo de Pagos'!I$7:I$506,'Flujo de Pagos'!E$7:E$506,B15,'Flujo de Pagos'!B$7:B$506,AI7)) | AJ15: =IF(B15="","",SUMIFS('Flujo de Pagos'!I$7:I$506,'Flujo de Pagos'!E$7:E$506,B15,'Flujo de Pagos'!B$7:B$506,AJ7)) | AK15: =IF(B15="","",SUMIFS('Flujo de Pagos'!I$7:I$506,'Flujo de Pagos'!E$7:E$506,B15,'Flujo de Pagos'!B$7:B$506,AK7)) | AL15: =IF(B15="","",SUMIFS('Flujo de Pagos'!I$7:I$506,'Flujo de Pagos'!E$7:E$506,B15,'Flujo de Pagos'!B$7:B$506,AL7)) | AM15: =IF(B15="","",SUM(C15:AL15))
B16: =IF(Presupuesto!B13="","",Presupuesto!B13) | C16: =IF(B16="","",SUMIFS('Flujo de Pagos'!I$7:I$506,'Flujo de Pagos'!E$7:E$506,B16,'Flujo de Pagos'!B$7:B$506,C7)) | D16: =IF(B16="","",SUMIFS('Flujo de Pagos'!I$7:I$506,'Flujo de Pagos'!E$7:E$506,B16,'Flujo de Pagos'!B$7:B$506,D7)) | E16: =IF(B16="","",SUMIFS('Flujo de Pagos'!I$7:I$506,'Flujo de Pagos'!E$7:E$506,B16,'Flujo de Pagos'!B$7:B$506,E7)) | F16: =IF(B16="","",SUMIFS('Flujo de Pagos'!I$7:I$506,'Flujo de Pagos'!E$7:E$506,B16,'Flujo de Pagos'!B$7:B$506,F7)) | G16: =IF(B16="","",SUMIFS('Flujo de Pagos'!I$7:I$506,'Flujo de Pagos'!E$7:E$506,B16,'Flujo de Pagos'!B$7:B$506,G7)) | H16: =IF(B16="","",SUMIFS('Flujo de Pagos'!I$7:I$506,'Flujo de Pagos'!E$7:E$506,B16,'Flujo de Pagos'!B$7:B$506,H7)) | I16: =IF(B16="","",SUMIFS('Flujo de Pagos'!I$7:I$506,'Flujo de Pagos'!E$7:E$506,B16,'Flujo de Pagos'!B$7:B$506,I7)) | J16: =IF(B16="","",SUMIFS('Flujo de Pagos'!I$7:I$506,'Flujo de Pagos'!E$7:E$506,B16,'Flujo de Pagos'!B$7:B$506,J7)) | K16: =IF(B16="","",SUMIFS('Flujo de Pagos'!I$7:I$506,'Flujo de Pagos'!E$7:E$506,B16,'Flujo de Pagos'!B$7:B$506,K7)) | L16: =IF(B16="","",SUMIFS('Flujo de Pagos'!I$7:I$506,'Flujo de Pagos'!E$7:E$506,B16,'Flujo de Pagos'!B$7:B$506,L7)) | M16: =IF(B16="","",SUMIFS('Flujo de Pagos'!I$7:I$506,'Flujo de Pagos'!E$7:E$506,B16,'Flujo de Pagos'!B$7:B$506,M7)) | N16: =IF(B16="","",SUMIFS('Flujo de Pagos'!I$7:I$506,'Flujo de Pagos'!E$7:E$506,B16,'Flujo de Pagos'!B$7:B$506,N7)) | O16: =IF(B16="","",SUMIFS('Flujo de Pagos'!I$7:I$506,'Flujo de Pagos'!E$7:E$506,B16,'Flujo de Pagos'!B$7:B$506,O7)) | P16: =IF(B16="","",SUMIFS('Flujo de Pagos'!I$7:I$506,'Flujo de Pagos'!E$7:E$506,B16,'Flujo de Pagos'!B$7:B$506,P7)) | Q16: =IF(B16="","",SUMIFS('Flujo de Pagos'!I$7:I$506,'Flujo de Pagos'!E$7:E$506,B16,'Flujo de Pagos'!B$7:B$506,Q7)) | R16: =IF(B16="","",SUMIFS('Flujo de Pagos'!I$7:I$506,'Flujo de Pagos'!E$7:E$506,B16,'Flujo de Pagos'!B$7:B$506,R7)) | S16: =IF(B16="","",SUMIFS('Flujo de Pagos'!I$7:I$506,'Flujo de Pagos'!E$7:E$506,B16,'Flujo de Pagos'!B$7:B$506,S7)) | T16: =IF(B16="","",SUMIFS('Flujo de Pagos'!I$7:I$506,'Flujo de Pagos'!E$7:E$506,B16,'Flujo de Pagos'!B$7:B$506,T7)) | U16: =IF(B16="","",SUMIFS('Flujo de Pagos'!I$7:I$506,'Flujo de Pagos'!E$7:E$506,B16,'Flujo de Pagos'!B$7:B$506,U7)) | V16: =IF(B16="","",SUMIFS('Flujo de Pagos'!I$7:I$506,'Flujo de Pagos'!E$7:E$506,B16,'Flujo de Pagos'!B$7:B$506,V7)) | W16: =IF(B16="","",SUMIFS('Flujo de Pagos'!I$7:I$506,'Flujo de Pagos'!E$7:E$506,B16,'Flujo de Pagos'!B$7:B$506,W7)) | X16: =IF(B16="","",SUMIFS('Flujo de Pagos'!I$7:I$506,'Flujo de Pagos'!E$7:E$506,B16,'Flujo de Pagos'!B$7:B$506,X7)) | Y16: =IF(B16="","",SUMIFS('Flujo de Pagos'!I$7:I$506,'Flujo de Pagos'!E$7:E$506,B16,'Flujo de Pagos'!B$7:B$506,Y7)) | Z16: =IF(B16="","",SUMIFS('Flujo de Pagos'!I$7:I$506,'Flujo de Pagos'!E$7:E$506,B16,'Flujo de Pagos'!B$7:B$506,Z7)) | AA16: =IF(B16="","",SUMIFS('Flujo de Pagos'!I$7:I$506,'Flujo de Pagos'!E$7:E$506,B16,'Flujo de Pagos'!B$7:B$506,AA7)) | AB16: =IF(B16="","",SUMIFS('Flujo de Pagos'!I$7:I$506,'Flujo de Pagos'!E$7:E$506,B16,'Flujo de Pagos'!B$7:B$506,AB7)) | AC16: =IF(B16="","",SUMIFS('Flujo de Pagos'!I$7:I$506,'Flujo de Pagos'!E$7:E$506,B16,'Flujo de Pagos'!B$7:B$506,AC7)) | AD16: =IF(B16="","",SUMIFS('Flujo de Pagos'!I$7:I$506,'Flujo de Pagos'!E$7:E$506,B16,'Flujo de Pagos'!B$7:B$506,AD7)) | AE16: =IF(B16="","",SUMIFS('Flujo de Pagos'!I$7:I$506,'Flujo de Pagos'!E$7:E$506,B16,'Flujo de Pagos'!B$7:B$506,AE7)) | AF16: =IF(B16="","",SUMIFS('Flujo de Pagos'!I$7:I$506,'Flujo de Pagos'!E$7:E$506,B16,'Flujo de Pagos'!B$7:B$506,AF7)) | AG16: =IF(B16="","",SUMIFS('Flujo de Pagos'!I$7:I$506,'Flujo de Pagos'!E$7:E$506,B16,'Flujo de Pagos'!B$7:B$506,AG7)) | AH16: =IF(B16="","",SUMIFS('Flujo de Pagos'!I$7:I$506,'Flujo de Pagos'!E$7:E$506,B16,'Flujo de Pagos'!B$7:B$506,AH7)) | AI16: =IF(B16="","",SUMIFS('Flujo de Pagos'!I$7:I$506,'Flujo de Pagos'!E$7:E$506,B16,'Flujo de Pagos'!B$7:B$506,AI7)) | AJ16: =IF(B16="","",SUMIFS('Flujo de Pagos'!I$7:I$506,'Flujo de Pagos'!E$7:E$506,B16,'Flujo de Pagos'!B$7:B$506,AJ7)) | AK16: =IF(B16="","",SUMIFS('Flujo de Pagos'!I$7:I$506,'Flujo de Pagos'!E$7:E$506,B16,'Flujo de Pagos'!B$7:B$506,AK7)) | AL16: =IF(B16="","",SUMIFS('Flujo de Pagos'!I$7:I$506,'Flujo de Pagos'!E$7:E$506,B16,'Flujo de Pagos'!B$7:B$506,AL7)) | AM16: =IF(B16="","",SUM(C16:AL16))
B17: =IF(Presupuesto!B14="","",Presupuesto!B14) | C17: =IF(B17="","",SUMIFS('Flujo de Pagos'!I$7:I$506,'Flujo de Pagos'!E$7:E$506,B17,'Flujo de Pagos'!B$7:B$506,C7)) | D17: =IF(B17="","",SUMIFS('Flujo de Pagos'!I$7:I$506,'Flujo de Pagos'!E$7:E$506,B17,'Flujo de Pagos'!B$7:B$506,D7)) | E17: =IF(B17="","",SUMIFS('Flujo de Pagos'!I$7:I$506,'Flujo de Pagos'!E$7:E$506,B17,'Flujo de Pagos'!B$7:B$506,E7)) | F17: =IF(B17="","",SUMIFS('Flujo de Pagos'!I$7:I$506,'Flujo de Pagos'!E$7:E$506,B17,'Flujo de Pagos'!B$7:B$506,F7)) | G17: =IF(B17="","",SUMIFS('Flujo de Pagos'!I$7:I$506,'Flujo de Pagos'!E$7:E$506,B17,'Flujo de Pagos'!B$7:B$506,G7)) | H17: =IF(B17="","",SUMIFS('Flujo de Pagos'!I$7:I$506,'Flujo de Pagos'!E$7:E$506,B17,'Flujo de Pagos'!B$7:B$506,H7)) | I17: =IF(B17="","",SUMIFS('Flujo de Pagos'!I$7:I$506,'Flujo de Pagos'!E$7:E$506,B17,'Flujo de Pagos'!B$7:B$506,I7)) | J17: =IF(B17="","",SUMIFS('Flujo de Pagos'!I$7:I$506,'Flujo de Pagos'!E$7:E$506,B17,'Flujo de Pagos'!B$7:B$506,J7)) | K17: =IF(B17="","",SUMIFS('Flujo de Pagos'!I$7:I$506,'Flujo de Pagos'!E$7:E$506,B17,'Flujo de Pagos'!B$7:B$506,K7)) | L17: =IF(B17="","",SUMIFS('Flujo de Pagos'!I$7:I$506,'Flujo de Pagos'!E$7:E$506,B17,'Flujo de Pagos'!B$7:B$506,L7)) | M17: =IF(B17="","",SUMIFS('Flujo de Pagos'!I$7:I$506,'Flujo de Pagos'!E$7:E$506,B17,'Flujo de Pagos'!B$7:B$506,M7)) | N17: =IF(B17="","",SUMIFS('Flujo de Pagos'!I$7:I$506,'Flujo de Pagos'!E$7:E$506,B17,'Flujo de Pagos'!B$7:B$506,N7)) | O17: =IF(B17="","",SUMIFS('Flujo de Pagos'!I$7:I$506,'Flujo de Pagos'!E$7:E$506,B17,'Flujo de Pagos'!B$7:B$506,O7)) | P17: =IF(B17="","",SUMIFS('Flujo de Pagos'!I$7:I$506,'Flujo de Pagos'!E$7:E$506,B17,'Flujo de Pagos'!B$7:B$506,P7)) | Q17: =IF(B17="","",SUMIFS('Flujo de Pagos'!I$7:I$506,'Flujo de Pagos'!E$7:E$506,B17,'Flujo de Pagos'!B$7:B$506,Q7)) | R17: =IF(B17="","",SUMIFS('Flujo de Pagos'!I$7:I$506,'Flujo de Pagos'!E$7:E$506,B17,'Flujo de Pagos'!B$7:B$506,R7)) | S17: =IF(B17="","",SUMIFS('Flujo de Pagos'!I$7:I$506,'Flujo de Pagos'!E$7:E$506,B17,'Flujo de Pagos'!B$7:B$506,S7)) | T17: =IF(B17="","",SUMIFS('Flujo de Pagos'!I$7:I$506,'Flujo de Pagos'!E$7:E$506,B17,'Flujo de Pagos'!B$7:B$506,T7)) | U17: =IF(B17="","",SUMIFS('Flujo de Pagos'!I$7:I$506,'Flujo de Pagos'!E$7:E$506,B17,'Flujo de Pagos'!B$7:B$506,U7)) | V17: =IF(B17="","",SUMIFS('Flujo de Pagos'!I$7:I$506,'Flujo de Pagos'!E$7:E$506,B17,'Flujo de Pagos'!B$7:B$506,V7)) | W17: =IF(B17="","",SUMIFS('Flujo de Pagos'!I$7:I$506,'Flujo de Pagos'!E$7:E$506,B17,'Flujo de Pagos'!B$7:B$506,W7)) | X17: =IF(B17="","",SUMIFS('Flujo de Pagos'!I$7:I$506,'Flujo de Pagos'!E$7:E$506,B17,'Flujo de Pagos'!B$7:B$506,X7)) | Y17: =IF(B17="","",SUMIFS('Flujo de Pagos'!I$7:I$506,'Flujo de Pagos'!E$7:E$506,B17,'Flujo de Pagos'!B$7:B$506,Y7)) | Z17: =IF(B17="","",SUMIFS('Flujo de Pagos'!I$7:I$506,'Flujo de Pagos'!E$7:E$506,B17,'Flujo de Pagos'!B$7:B$506,Z7)) | AA17: =IF(B17="","",SUMIFS('Flujo de Pagos'!I$7:I$506,'Flujo de Pagos'!E$7:E$506,B17,'Flujo de Pagos'!B$7:B$506,AA7)) | AB17: =IF(B17="","",SUMIFS('Flujo de Pagos'!I$7:I$506,'Flujo de Pagos'!E$7:E$506,B17,'Flujo de Pagos'!B$7:B$506,AB7)) | AC17: =IF(B17="","",SUMIFS('Flujo de Pagos'!I$7:I$506,'Flujo de Pagos'!E$7:E$506,B17,'Flujo de Pagos'!B$7:B$506,AC7)) | AD17: =IF(B17="","",SUMIFS('Flujo de Pagos'!I$7:I$506,'Flujo de Pagos'!E$7:E$506,B17,'Flujo de Pagos'!B$7:B$506,AD7)) | AE17: =IF(B17="","",SUMIFS('Flujo de Pagos'!I$7:I$506,'Flujo de Pagos'!E$7:E$506,B17,'Flujo de Pagos'!B$7:B$506,AE7)) | AF17: =IF(B17="","",SUMIFS('Flujo de Pagos'!I$7:I$506,'Flujo de Pagos'!E$7:E$506,B17,'Flujo de Pagos'!B$7:B$506,AF7)) | AG17: =IF(B17="","",SUMIFS('Flujo de Pagos'!I$7:I$506,'Flujo de Pagos'!E$7:E$506,B17,'Flujo de Pagos'!B$7:B$506,AG7)) | AH17: =IF(B17="","",SUMIFS('Flujo de Pagos'!I$7:I$506,'Flujo de Pagos'!E$7:E$506,B17,'Flujo de Pagos'!B$7:B$506,AH7)) | AI17: =IF(B17="","",SUMIFS('Flujo de Pagos'!I$7:I$506,'Flujo de Pagos'!E$7:E$506,B17,'Flujo de Pagos'!B$7:B$506,AI7)) | AJ17: =IF(B17="","",SUMIFS('Flujo de Pagos'!I$7:I$506,'Flujo de Pagos'!E$7:E$506,B17,'Flujo de Pagos'!B$7:B$506,AJ7)) | AK17: =IF(B17="","",SUMIFS('Flujo de Pagos'!I$7:I$506,'Flujo de Pagos'!E$7:E$506,B17,'Flujo de Pagos'!B$7:B$506,AK7)) | AL17: =IF(B17="","",SUMIFS('Flujo de Pagos'!I$7:I$506,'Flujo de Pagos'!E$7:E$506,B17,'Flujo de Pagos'!B$7:B$506,AL7)) | AM17: =IF(B17="","",SUM(C17:AL17))
B18: =IF(Presupuesto!B15="","",Presupuesto!B15) | C18: =IF(B18="","",SUMIFS('Flujo de Pagos'!I$7:I$506,'Flujo de Pagos'!E$7:E$506,B18,'Flujo de Pagos'!B$7:B$506,C7)) | D18: =IF(B18="","",SUMIFS('Flujo de Pagos'!I$7:I$506,'Flujo de Pagos'!E$7:E$506,B18,'Flujo de Pagos'!B$7:B$506,D7)) | E18: =IF(B18="","",SUMIFS('Flujo de Pagos'!I$7:I$506,'Flujo de Pagos'!E$7:E$506,B18,'Flujo de Pagos'!B$7:B$506,E7)) | F18: =IF(B18="","",SUMIFS('Flujo de Pagos'!I$7:I$506,'Flujo de Pagos'!E$7:E$506,B18,'Flujo de Pagos'!B$7:B$506,F7)) | G18: =IF(B18="","",SUMIFS('Flujo de Pagos'!I$7:I$506,'Flujo de Pagos'!E$7:E$506,B18,'Flujo de Pagos'!B$7:B$506,G7)) | H18: =IF(B18="","",SUMIFS('Flujo de Pagos'!I$7:I$506,'Flujo de Pagos'!E$7:E$506,B18,'Flujo de Pagos'!B$7:B$506,H7)) | I18: =IF(B18="","",SUMIFS('Flujo de Pagos'!I$7:I$506,'Flujo de Pagos'!E$7:E$506,B18,'Flujo de Pagos'!B$7:B$506,I7)) | J18: =IF(B18="","",SUMIFS('Flujo de Pagos'!I$7:I$506,'Flujo de Pagos'!E$7:E$506,B18,'Flujo de Pagos'!B$7:B$506,J7)) | K18: =IF(B18="","",SUMIFS('Flujo de Pagos'!I$7:I$506,'Flujo de Pagos'!E$7:E$506,B18,'Flujo de Pagos'!B$7:B$506,K7)) | L18: =IF(B18="","",SUMIFS('Flujo de Pagos'!I$7:I$506,'Flujo de Pagos'!E$7:E$506,B18,'Flujo de Pagos'!B$7:B$506,L7)) | M18: =IF(B18="","",SUMIFS('Flujo de Pagos'!I$7:I$506,'Flujo de Pagos'!E$7:E$506,B18,'Flujo de Pagos'!B$7:B$506,M7)) | N18: =IF(B18="","",SUMIFS('Flujo de Pagos'!I$7:I$506,'Flujo de Pagos'!E$7:E$506,B18,'Flujo de Pagos'!B$7:B$506,N7)) | O18: =IF(B18="","",SUMIFS('Flujo de Pagos'!I$7:I$506,'Flujo de Pagos'!E$7:E$506,B18,'Flujo de Pagos'!B$7:B$506,O7)) | P18: =IF(B18="","",SUMIFS('Flujo de Pagos'!I$7:I$506,'Flujo de Pagos'!E$7:E$506,B18,'Flujo de Pagos'!B$7:B$506,P7)) | Q18: =IF(B18="","",SUMIFS('Flujo de Pagos'!I$7:I$506,'Flujo de Pagos'!E$7:E$506,B18,'Flujo de Pagos'!B$7:B$506,Q7)) | R18: =IF(B18="","",SUMIFS('Flujo de Pagos'!I$7:I$506,'Flujo de Pagos'!E$7:E$506,B18,'Flujo de Pagos'!B$7:B$506,R7)) | S18: =IF(B18="","",SUMIFS('Flujo de Pagos'!I$7:I$506,'Flujo de Pagos'!E$7:E$506,B18,'Flujo de Pagos'!B$7:B$506,S7)) | T18: =IF(B18="","",SUMIFS('Flujo de Pagos'!I$7:I$506,'Flujo de Pagos'!E$7:E$506,B18,'Flujo de Pagos'!B$7:B$506,T7)) | U18: =IF(B18="","",SUMIFS('Flujo de Pagos'!I$7:I$506,'Flujo de Pagos'!E$7:E$506,B18,'Flujo de Pagos'!B$7:B$506,U7)) | V18: =IF(B18="","",SUMIFS('Flujo de Pagos'!I$7:I$506,'Flujo de Pagos'!E$7:E$506,B18,'Flujo de Pagos'!B$7:B$506,V7)) | W18: =IF(B18="","",SUMIFS('Flujo de Pagos'!I$7:I$506,'Flujo de Pagos'!E$7:E$506,B18,'Flujo de Pagos'!B$7:B$506,W7)) | X18: =IF(B18="","",SUMIFS('Flujo de Pagos'!I$7:I$506,'Flujo de Pagos'!E$7:E$506,B18,'Flujo de Pagos'!B$7:B$506,X7)) | Y18: =IF(B18="","",SUMIFS('Flujo de Pagos'!I$7:I$506,'Flujo de Pagos'!E$7:E$506,B18,'Flujo de Pagos'!B$7:B$506,Y7)) | Z18: =IF(B18="","",SUMIFS('Flujo de Pagos'!I$7:I$506,'Flujo de Pagos'!E$7:E$506,B18,'Flujo de Pagos'!B$7:B$506,Z7)) | AA18: =IF(B18="","",SUMIFS('Flujo de Pagos'!I$7:I$506,'Flujo de Pagos'!E$7:E$506,B18,'Flujo de Pagos'!B$7:B$506,AA7)) | AB18: =IF(B18="","",SUMIFS('Flujo de Pagos'!I$7:I$506,'Flujo de Pagos'!E$7:E$506,B18,'Flujo de Pagos'!B$7:B$506,AB7)) | AC18: =IF(B18="","",SUMIFS('Flujo de Pagos'!I$7:I$506,'Flujo de Pagos'!E$7:E$506,B18,'Flujo de Pagos'!B$7:B$506,AC7)) | AD18: =IF(B18="","",SUMIFS('Flujo de Pagos'!I$7:I$506,'Flujo de Pagos'!E$7:E$506,B18,'Flujo de Pagos'!B$7:B$506,AD7)) | AE18: =IF(B18="","",SUMIFS('Flujo de Pagos'!I$7:I$506,'Flujo de Pagos'!E$7:E$506,B18,'Flujo de Pagos'!B$7:B$506,AE7)) | AF18: =IF(B18="","",SUMIFS('Flujo de Pagos'!I$7:I$506,'Flujo de Pagos'!E$7:E$506,B18,'Flujo de Pagos'!B$7:B$506,AF7)) | AG18: =IF(B18="","",SUMIFS('Flujo de Pagos'!I$7:I$506,'Flujo de Pagos'!E$7:E$506,B18,'Flujo de Pagos'!B$7:B$506,AG7)) | AH18: =IF(B18="","",SUMIFS('Flujo de Pagos'!I$7:I$506,'Flujo de Pagos'!E$7:E$506,B18,'Flujo de Pagos'!B$7:B$506,AH7)) | AI18: =IF(B18="","",SUMIFS('Flujo de Pagos'!I$7:I$506,'Flujo de Pagos'!E$7:E$506,B18,'Flujo de Pagos'!B$7:B$506,AI7)) | AJ18: =IF(B18="","",SUMIFS('Flujo de Pagos'!I$7:I$506,'Flujo de Pagos'!E$7:E$506,B18,'Flujo de Pagos'!B$7:B$506,AJ7)) | AK18: =IF(B18="","",SUMIFS('Flujo de Pagos'!I$7:I$506,'Flujo de Pagos'!E$7:E$506,B18,'Flujo de Pagos'!B$7:B$506,AK7)) | AL18: =IF(B18="","",SUMIFS('Flujo de Pagos'!I$7:I$506,'Flujo de Pagos'!E$7:E$506,B18,'Flujo de Pagos'!B$7:B$506,AL7)) | AM18: =IF(B18="","",SUM(C18:AL18))
B19: =IF(Presupuesto!B16="","",Presupuesto!B16) | C19: =IF(B19="","",SUMIFS('Flujo de Pagos'!I$7:I$506,'Flujo de Pagos'!E$7:E$506,B19,'Flujo de Pagos'!B$7:B$506,C7)) | D19: =IF(B19="","",SUMIFS('Flujo de Pagos'!I$7:I$506,'Flujo de Pagos'!E$7:E$506,B19,'Flujo de Pagos'!B$7:B$506,D7)) | E19: =IF(B19="","",SUMIFS('Flujo de Pagos'!I$7:I$506,'Flujo de Pagos'!E$7:E$506,B19,'Flujo de Pagos'!B$7:B$506,E7)) | F19: =IF(B19="","",SUMIFS('Flujo de Pagos'!I$7:I$506,'Flujo de Pagos'!E$7:E$506,B19,'Flujo de Pagos'!B$7:B$506,F7)) | G19: =IF(B19="","",SUMIFS('Flujo de Pagos'!I$7:I$506,'Flujo de Pagos'!E$7:E$506,B19,'Flujo de Pagos'!B$7:B$506,G7)) | H19: =IF(B19="","",SUMIFS('Flujo de Pagos'!I$7:I$506,'Flujo de Pagos'!E$7:E$506,B19,'Flujo de Pagos'!B$7:B$506,H7)) | I19: =IF(B19="","",SUMIFS('Flujo de Pagos'!I$7:I$506,'Flujo de Pagos'!E$7:E$506,B19,'Flujo de Pagos'!B$7:B$506,I7)) | J19: =IF(B19="","",SUMIFS('Flujo de Pagos'!I$7:I$506,'Flujo de Pagos'!E$7:E$506,B19,'Flujo de Pagos'!B$7:B$506,J7)) | K19: =IF(B19="","",SUMIFS('Flujo de Pagos'!I$7:I$506,'Flujo de Pagos'!E$7:E$506,B19,'Flujo de Pagos'!B$7:B$506,K7)) | L19: =IF(B19="","",SUMIFS('Flujo de Pagos'!I$7:I$506,'Flujo de Pagos'!E$7:E$506,B19,'Flujo de Pagos'!B$7:B$506,L7)) | M19: =IF(B19="","",SUMIFS('Flujo de Pagos'!I$7:I$506,'Flujo de Pagos'!E$7:E$506,B19,'Flujo de Pagos'!B$7:B$506,M7)) | N19: =IF(B19="","",SUMIFS('Flujo de Pagos'!I$7:I$506,'Flujo de Pagos'!E$7:E$506,B19,'Flujo de Pagos'!B$7:B$506,N7)) | O19: =IF(B19="","",SUMIFS('Flujo de Pagos'!I$7:I$506,'Flujo de Pagos'!E$7:E$506,B19,'Flujo de Pagos'!B$7:B$506,O7)) | P19: =IF(B19="","",SUMIFS('Flujo de Pagos'!I$7:I$506,'Flujo de Pagos'!E$7:E$506,B19,'Flujo de Pagos'!B$7:B$506,P7)) | Q19: =IF(B19="","",SUMIFS('Flujo de Pagos'!I$7:I$506,'Flujo de Pagos'!E$7:E$506,B19,'Flujo de Pagos'!B$7:B$506,Q7)) | R19: =IF(B19="","",SUMIFS('Flujo de Pagos'!I$7:I$506,'Flujo de Pagos'!E$7:E$506,B19,'Flujo de Pagos'!B$7:B$506,R7)) | S19: =IF(B19="","",SUMIFS('Flujo de Pagos'!I$7:I$506,'Flujo de Pagos'!E$7:E$506,B19,'Flujo de Pagos'!B$7:B$506,S7)) | T19: =IF(B19="","",SUMIFS('Flujo de Pagos'!I$7:I$506,'Flujo de Pagos'!E$7:E$506,B19,'Flujo de Pagos'!B$7:B$506,T7)) | U19: =IF(B19="","",SUMIFS('Flujo de Pagos'!I$7:I$506,'Flujo de Pagos'!E$7:E$506,B19,'Flujo de Pagos'!B$7:B$506,U7)) | V19: =IF(B19="","",SUMIFS('Flujo de Pagos'!I$7:I$506,'Flujo de Pagos'!E$7:E$506,B19,'Flujo de Pagos'!B$7:B$506,V7)) | W19: =IF(B19="","",SUMIFS('Flujo de Pagos'!I$7:I$506,'Flujo de Pagos'!E$7:E$506,B19,'Flujo de Pagos'!B$7:B$506,W7)) | X19: =IF(B19="","",SUMIFS('Flujo de Pagos'!I$7:I$506,'Flujo de Pagos'!E$7:E$506,B19,'Flujo de Pagos'!B$7:B$506,X7)) | Y19: =IF(B19="","",SUMIFS('Flujo de Pagos'!I$7:I$506,'Flujo de Pagos'!E$7:E$506,B19,'Flujo de Pagos'!B$7:B$506,Y7)) | Z19: =IF(B19="","",SUMIFS('Flujo de Pagos'!I$7:I$506,'Flujo de Pagos'!E$7:E$506,B19,'Flujo de Pagos'!B$7:B$506,Z7)) | AA19: =IF(B19="","",SUMIFS('Flujo de Pagos'!I$7:I$506,'Flujo de Pagos'!E$7:E$506,B19,'Flujo de Pagos'!B$7:B$506,AA7)) | AB19: =IF(B19="","",SUMIFS('Flujo de Pagos'!I$7:I$506,'Flujo de Pagos'!E$7:E$506,B19,'Flujo de Pagos'!B$7:B$506,AB7)) | AC19: =IF(B19="","",SUMIFS('Flujo de Pagos'!I$7:I$506,'Flujo de Pagos'!E$7:E$506,B19,'Flujo de Pagos'!B$7:B$506,AC7)) | AD19: =IF(B19="","",SUMIFS('Flujo de Pagos'!I$7:I$506,'Flujo de Pagos'!E$7:E$506,B19,'Flujo de Pagos'!B$7:B$506,AD7)) | AE19: =IF(B19="","",SUMIFS('Flujo de Pagos'!I$7:I$506,'Flujo de Pagos'!E$7:E$506,B19,'Flujo de Pagos'!B$7:B$506,AE7)) | AF19: =IF(B19="","",SUMIFS('Flujo de Pagos'!I$7:I$506,'Flujo de Pagos'!E$7:E$506,B19,'Flujo de Pagos'!B$7:B$506,AF7)) | AG19: =IF(B19="","",SUMIFS('Flujo de Pagos'!I$7:I$506,'Flujo de Pagos'!E$7:E$506,B19,'Flujo de Pagos'!B$7:B$506,AG7)) | AH19: =IF(B19="","",SUMIFS('Flujo de Pagos'!I$7:I$506,'Flujo de Pagos'!E$7:E$506,B19,'Flujo de Pagos'!B$7:B$506,AH7)) | AI19: =IF(B19="","",SUMIFS('Flujo de Pagos'!I$7:I$506,'Flujo de Pagos'!E$7:E$506,B19,'Flujo de Pagos'!B$7:B$506,AI7)) | AJ19: =IF(B19="","",SUMIFS('Flujo de Pagos'!I$7:I$506,'Flujo de Pagos'!E$7:E$506,B19,'Flujo de Pagos'!B$7:B$506,AJ7)) | AK19: =IF(B19="","",SUMIFS('Flujo de Pagos'!I$7:I$506,'Flujo de Pagos'!E$7:E$506,B19,'Flujo de Pagos'!B$7:B$506,AK7)) | AL19: =IF(B19="","",SUMIFS('Flujo de Pagos'!I$7:I$506,'Flujo de Pagos'!E$7:E$506,B19,'Flujo de Pagos'!B$7:B$506,AL7)) | AM19: =IF(B19="","",SUM(C19:AL19))
B20: =IF(Presupuesto!B17="","",Presupuesto!B17) | C20: =IF(B20="","",SUMIFS('Flujo de Pagos'!I$7:I$506,'Flujo de Pagos'!E$7:E$506,B20,'Flujo de Pagos'!B$7:B$506,C7)) | D20: =IF(B20="","",SUMIFS('Flujo de Pagos'!I$7:I$506,'Flujo de Pagos'!E$7:E$506,B20,'Flujo de Pagos'!B$7:B$506,D7)) | E20: =IF(B20="","",SUMIFS('Flujo de Pagos'!I$7:I$506,'Flujo de Pagos'!E$7:E$506,B20,'Flujo de Pagos'!B$7:B$506,E7)) | F20: =IF(B20="","",SUMIFS('Flujo de Pagos'!I$7:I$506,'Flujo de Pagos'!E$7:E$506,B20,'Flujo de Pagos'!B$7:B$506,F7)) | G20: =IF(B20="","",SUMIFS('Flujo de Pagos'!I$7:I$506,'Flujo de Pagos'!E$7:E$506,B20,'Flujo de Pagos'!B$7:B$506,G7)) | H20: =IF(B20="","",SUMIFS('Flujo de Pagos'!I$7:I$506,'Flujo de Pagos'!E$7:E$506,B20,'Flujo de Pagos'!B$7:B$506,H7)) | I20: =IF(B20="","",SUMIFS('Flujo de Pagos'!I$7:I$506,'Flujo de Pagos'!E$7:E$506,B20,'Flujo de Pagos'!B$7:B$506,I7)) | J20: =IF(B20="","",SUMIFS('Flujo de Pagos'!I$7:I$506,'Flujo de Pagos'!E$7:E$506,B20,'Flujo de Pagos'!B$7:B$506,J7)) | K20: =IF(B20="","",SUMIFS('Flujo de Pagos'!I$7:I$506,'Flujo de Pagos'!E$7:E$506,B20,'Flujo de Pagos'!B$7:B$506,K7)) | L20: =IF(B20="","",SUMIFS('Flujo de Pagos'!I$7:I$506,'Flujo de Pagos'!E$7:E$506,B20,'Flujo de Pagos'!B$7:B$506,L7)) | M20: =IF(B20="","",SUMIFS('Flujo de Pagos'!I$7:I$506,'Flujo de Pagos'!E$7:E$506,B20,'Flujo de Pagos'!B$7:B$506,M7)) | N20: =IF(B20="","",SUMIFS('Flujo de Pagos'!I$7:I$506,'Flujo de Pagos'!E$7:E$506,B20,'Flujo de Pagos'!B$7:B$506,N7)) | O20: =IF(B20="","",SUMIFS('Flujo de Pagos'!I$7:I$506,'Flujo de Pagos'!E$7:E$506,B20,'Flujo de Pagos'!B$7:B$506,O7)) | P20: =IF(B20="","",SUMIFS('Flujo de Pagos'!I$7:I$506,'Flujo de Pagos'!E$7:E$506,B20,'Flujo de Pagos'!B$7:B$506,P7)) | Q20: =IF(B20="","",SUMIFS('Flujo de Pagos'!I$7:I$506,'Flujo de Pagos'!E$7:E$506,B20,'Flujo de Pagos'!B$7:B$506,Q7)) | R20: =IF(B20="","",SUMIFS('Flujo de Pagos'!I$7:I$506,'Flujo de Pagos'!E$7:E$506,B20,'Flujo de Pagos'!B$7:B$506,R7)) | S20: =IF(B20="","",SUMIFS('Flujo de Pagos'!I$7:I$506,'Flujo de Pagos'!E$7:E$506,B20,'Flujo de Pagos'!B$7:B$506,S7)) | T20: =IF(B20="","",SUMIFS('Flujo de Pagos'!I$7:I$506,'Flujo de Pagos'!E$7:E$506,B20,'Flujo de Pagos'!B$7:B$506,T7)) | U20: =IF(B20="","",SUMIFS('Flujo de Pagos'!I$7:I$506,'Flujo de Pagos'!E$7:E$506,B20,'Flujo de Pagos'!B$7:B$506,U7)) | V20: =IF(B20="","",SUMIFS('Flujo de Pagos'!I$7:I$506,'Flujo de Pagos'!E$7:E$506,B20,'Flujo de Pagos'!B$7:B$506,V7)) | W20: =IF(B20="","",SUMIFS('Flujo de Pagos'!I$7:I$506,'Flujo de Pagos'!E$7:E$506,B20,'Flujo de Pagos'!B$7:B$506,W7)) | X20: =IF(B20="","",SUMIFS('Flujo de Pagos'!I$7:I$506,'Flujo de Pagos'!E$7:E$506,B20,'Flujo de Pagos'!B$7:B$506,X7)) | Y20: =IF(B20="","",SUMIFS('Flujo de Pagos'!I$7:I$506,'Flujo de Pagos'!E$7:E$506,B20,'Flujo de Pagos'!B$7:B$506,Y7)) | Z20: =IF(B20="","",SUMIFS('Flujo de Pagos'!I$7:I$506,'Flujo de Pagos'!E$7:E$506,B20,'Flujo de Pagos'!B$7:B$506,Z7)) | AA20: =IF(B20="","",SUMIFS('Flujo de Pagos'!I$7:I$506,'Flujo de Pagos'!E$7:E$506,B20,'Flujo de Pagos'!B$7:B$506,AA7)) | AB20: =IF(B20="","",SUMIFS('Flujo de Pagos'!I$7:I$506,'Flujo de Pagos'!E$7:E$506,B20,'Flujo de Pagos'!B$7:B$506,AB7)) | AC20: =IF(B20="","",SUMIFS('Flujo de Pagos'!I$7:I$506,'Flujo de Pagos'!E$7:E$506,B20,'Flujo de Pagos'!B$7:B$506,AC7)) | AD20: =IF(B20="","",SUMIFS('Flujo de Pagos'!I$7:I$506,'Flujo de Pagos'!E$7:E$506,B20,'Flujo de Pagos'!B$7:B$506,AD7)) | AE20: =IF(B20="","",SUMIFS('Flujo de Pagos'!I$7:I$506,'Flujo de Pagos'!E$7:E$506,B20,'Flujo de Pagos'!B$7:B$506,AE7)) | AF20: =IF(B20="","",SUMIFS('Flujo de Pagos'!I$7:I$506,'Flujo de Pagos'!E$7:E$506,B20,'Flujo de Pagos'!B$7:B$506,AF7)) | AG20: =IF(B20="","",SUMIFS('Flujo de Pagos'!I$7:I$506,'Flujo de Pagos'!E$7:E$506,B20,'Flujo de Pagos'!B$7:B$506,AG7)) | AH20: =IF(B20="","",SUMIFS('Flujo de Pagos'!I$7:I$506,'Flujo de Pagos'!E$7:E$506,B20,'Flujo de Pagos'!B$7:B$506,AH7)) | AI20: =IF(B20="","",SUMIFS('Flujo de Pagos'!I$7:I$506,'Flujo de Pagos'!E$7:E$506,B20,'Flujo de Pagos'!B$7:B$506,AI7)) | AJ20: =IF(B20="","",SUMIFS('Flujo de Pagos'!I$7:I$506,'Flujo de Pagos'!E$7:E$506,B20,'Flujo de Pagos'!B$7:B$506,AJ7)) | AK20: =IF(B20="","",SUMIFS('Flujo de Pagos'!I$7:I$506,'Flujo de Pagos'!E$7:E$506,B20,'Flujo de Pagos'!B$7:B$506,AK7)) | AL20: =IF(B20="","",SUMIFS('Flujo de Pagos'!I$7:I$506,'Flujo de Pagos'!E$7:E$506,B20,'Flujo de Pagos'!B$7:B$506,AL7)) | AM20: =IF(B20="","",SUM(C20:AL20))
